[2023-04-04 14:50:12,974] {taskinstance.py:1159} INFO - Dependencies all met for <TaskInstance: dados_climaticos.extrai_dados scheduled__2022-10-17T00:00:00+00:00 [queued]>
[2023-04-04 14:50:12,977] {taskinstance.py:1159} INFO - Dependencies all met for <TaskInstance: dados_climaticos.extrai_dados scheduled__2022-10-17T00:00:00+00:00 [queued]>
[2023-04-04 14:50:12,977] {taskinstance.py:1356} INFO - 
--------------------------------------------------------------------------------
[2023-04-04 14:50:12,977] {taskinstance.py:1357} INFO - Starting attempt 1 of 1
[2023-04-04 14:50:12,977] {taskinstance.py:1358} INFO - 
--------------------------------------------------------------------------------
[2023-04-04 14:50:12,998] {taskinstance.py:1377} INFO - Executing <Task(PythonOperator): extrai_dados> on 2022-10-17 00:00:00+00:00
[2023-04-04 14:50:13,002] {standard_task_runner.py:52} INFO - Started process 14875 to run task
[2023-04-04 14:50:13,003] {standard_task_runner.py:79} INFO - Running: ['airflow', 'tasks', 'run', 'dados_climaticos', 'extrai_dados', 'scheduled__2022-10-17T00:00:00+00:00', '--job-id', '44', '--raw', '--subdir', 'DAGS_FOLDER/dados_climaticos.py', '--cfg-path', '/tmp/tmpd2dbba2w', '--error-file', '/tmp/tmpz4tv_k9s']
[2023-04-04 14:50:13,004] {standard_task_runner.py:80} INFO - Job 44: Subtask extrai_dados
[2023-04-04 14:50:13,056] {task_command.py:370} INFO - Running <TaskInstance: dados_climaticos.extrai_dados scheduled__2022-10-17T00:00:00+00:00 [running]> on host bruno-H610M-H-DDR4
[2023-04-04 14:50:13,109] {taskinstance.py:1569} INFO - Exporting the following env vars:
AIRFLOW_CTX_DAG_OWNER=airflow
AIRFLOW_CTX_DAG_ID=dados_climaticos
AIRFLOW_CTX_TASK_ID=extrai_dados
AIRFLOW_CTX_EXECUTION_DATE=2022-10-17T00:00:00+00:00
AIRFLOW_CTX_TRY_NUMBER=1
AIRFLOW_CTX_DAG_RUN_ID=scheduled__2022-10-17T00:00:00+00:00
[2023-04-04 14:50:13,787] {taskinstance.py:1889} ERROR - Task failed with exception
Traceback (most recent call last):
  File "/home/bruno/Documents/airflow_alura/venv/lib/python3.10/site-packages/airflow/operators/python.py", line 171, in execute
    return_value = self.execute_callable()
  File "/home/bruno/Documents/airflow_alura/venv/lib/python3.10/site-packages/airflow/operators/python.py", line 189, in execute_callable
    return self.python_callable(*self.op_args, **self.op_kwargs)
  File "/home/bruno/Documents/airflow_alura/dags/dados_climaticos.py", line 27, in extrai_dados
    dados = pd.read_csv(URL)
  File "/home/bruno/Documents/airflow_alura/venv/lib/python3.10/site-packages/pandas/io/parsers/readers.py", line 912, in read_csv
    return _read(filepath_or_buffer, kwds)
  File "/home/bruno/Documents/airflow_alura/venv/lib/python3.10/site-packages/pandas/io/parsers/readers.py", line 577, in _read
    parser = TextFileReader(filepath_or_buffer, **kwds)
  File "/home/bruno/Documents/airflow_alura/venv/lib/python3.10/site-packages/pandas/io/parsers/readers.py", line 1407, in __init__
    self._engine = self._make_engine(f, self.engine)
  File "/home/bruno/Documents/airflow_alura/venv/lib/python3.10/site-packages/pandas/io/parsers/readers.py", line 1661, in _make_engine
    self.handles = get_handle(
  File "/home/bruno/Documents/airflow_alura/venv/lib/python3.10/site-packages/pandas/io/common.py", line 716, in get_handle
    ioargs = _get_filepath_or_buffer(
  File "/home/bruno/Documents/airflow_alura/venv/lib/python3.10/site-packages/pandas/io/common.py", line 368, in _get_filepath_or_buffer
    with urlopen(req_info) as req:
  File "/home/bruno/Documents/airflow_alura/venv/lib/python3.10/site-packages/pandas/io/common.py", line 270, in urlopen
    return urllib.request.urlopen(*args, **kwargs)
  File "/usr/lib/python3.10/urllib/request.py", line 216, in urlopen
    return opener.open(url, data, timeout)
  File "/usr/lib/python3.10/urllib/request.py", line 525, in open
    response = meth(req, response)
  File "/usr/lib/python3.10/urllib/request.py", line 634, in http_response
    response = self.parent.error(
  File "/usr/lib/python3.10/urllib/request.py", line 563, in error
    return self._call_chain(*args)
  File "/usr/lib/python3.10/urllib/request.py", line 496, in _call_chain
    result = func(*args)
  File "/usr/lib/python3.10/urllib/request.py", line 643, in http_error_default
    raise HTTPError(req.full_url, code, msg, hdrs, fp)
urllib.error.HTTPError: HTTP Error 401: 
[2023-04-04 14:50:13,793] {taskinstance.py:1395} INFO - Marking task as FAILED. dag_id=dados_climaticos, task_id=extrai_dados, execution_date=20221017T000000, start_date=20230404T175012, end_date=20230404T175013
[2023-04-04 14:50:13,807] {standard_task_runner.py:92} ERROR - Failed to execute job 44 for task extrai_dados (HTTP Error 401: ; 14875)
[2023-04-04 14:50:13,817] {local_task_job.py:156} INFO - Task exited with return code 1
[2023-04-04 14:50:13,836] {local_task_job.py:273} INFO - 0 downstream tasks scheduled from follow-on schedule check
[2023-04-04 14:50:13,839] {dagrun.py:547} ERROR - Marking run <DagRun dados_climaticos @ 2022-10-17 00:00:00+00:00: scheduled__2022-10-17T00:00:00+00:00, externally triggered: False> failed
[2023-04-04 14:50:13,840] {dagrun.py:607} INFO - DagRun Finished: dag_id=dados_climaticos, execution_date=2022-10-17 00:00:00+00:00, run_id=scheduled__2022-10-17T00:00:00+00:00, run_start_date=2023-04-04 17:50:08.959893+00:00, run_end_date=2023-04-04 17:50:13.840114+00:00, run_duration=4.880221, state=failed, external_trigger=False, run_type=scheduled, data_interval_start=2022-10-17 00:00:00+00:00, data_interval_end=2022-10-24 00:00:00+00:00, dag_hash=2c06d76ca885ba906a47a8136955e4b2
[2023-04-04 15:15:23,165] {taskinstance.py:1159} INFO - Dependencies all met for <TaskInstance: dados_climaticos.extrai_dados scheduled__2022-10-17T00:00:00+00:00 [queued]>
[2023-04-04 15:15:23,179] {taskinstance.py:1159} INFO - Dependencies all met for <TaskInstance: dados_climaticos.extrai_dados scheduled__2022-10-17T00:00:00+00:00 [queued]>
[2023-04-04 15:15:23,179] {taskinstance.py:1356} INFO - 
--------------------------------------------------------------------------------
[2023-04-04 15:15:23,179] {taskinstance.py:1357} INFO - Starting attempt 1 of 1
[2023-04-04 15:15:23,179] {taskinstance.py:1358} INFO - 
--------------------------------------------------------------------------------
[2023-04-04 15:15:23,202] {taskinstance.py:1377} INFO - Executing <Task(PythonOperator): extrai_dados> on 2022-10-17 00:00:00+00:00
[2023-04-04 15:15:23,205] {standard_task_runner.py:52} INFO - Started process 8771 to run task
[2023-04-04 15:15:23,208] {standard_task_runner.py:79} INFO - Running: ['airflow', 'tasks', 'run', 'dados_climaticos', 'extrai_dados', 'scheduled__2022-10-17T00:00:00+00:00', '--job-id', '43', '--raw', '--subdir', 'DAGS_FOLDER/dados_climaticos.py', '--cfg-path', '/tmp/tmp9vubpayr', '--error-file', '/tmp/tmpujhjvk2g']
[2023-04-04 15:15:23,208] {standard_task_runner.py:80} INFO - Job 43: Subtask extrai_dados
[2023-04-04 15:15:23,249] {task_command.py:370} INFO - Running <TaskInstance: dados_climaticos.extrai_dados scheduled__2022-10-17T00:00:00+00:00 [running]> on host bruno-H610M-H-DDR4
[2023-04-04 15:15:23,304] {taskinstance.py:1569} INFO - Exporting the following env vars:
AIRFLOW_CTX_DAG_OWNER=airflow
AIRFLOW_CTX_DAG_ID=dados_climaticos
AIRFLOW_CTX_TASK_ID=extrai_dados
AIRFLOW_CTX_EXECUTION_DATE=2022-10-17T00:00:00+00:00
AIRFLOW_CTX_TRY_NUMBER=1
AIRFLOW_CTX_DAG_RUN_ID=scheduled__2022-10-17T00:00:00+00:00
[2023-04-04 15:15:24,003] {taskinstance.py:1889} ERROR - Task failed with exception
Traceback (most recent call last):
  File "/home/bruno/Documents/airflow_alura/venv/lib/python3.10/site-packages/airflow/operators/python.py", line 171, in execute
    return_value = self.execute_callable()
  File "/home/bruno/Documents/airflow_alura/venv/lib/python3.10/site-packages/airflow/operators/python.py", line 189, in execute_callable
    return self.python_callable(*self.op_args, **self.op_kwargs)
  File "/home/bruno/Documents/airflow_alura/dags/dados_climaticos.py", line 27, in extrai_dados
    dados = pd.read_csv(URL)
  File "/home/bruno/Documents/airflow_alura/venv/lib/python3.10/site-packages/pandas/io/parsers/readers.py", line 912, in read_csv
    return _read(filepath_or_buffer, kwds)
  File "/home/bruno/Documents/airflow_alura/venv/lib/python3.10/site-packages/pandas/io/parsers/readers.py", line 577, in _read
    parser = TextFileReader(filepath_or_buffer, **kwds)
  File "/home/bruno/Documents/airflow_alura/venv/lib/python3.10/site-packages/pandas/io/parsers/readers.py", line 1407, in __init__
    self._engine = self._make_engine(f, self.engine)
  File "/home/bruno/Documents/airflow_alura/venv/lib/python3.10/site-packages/pandas/io/parsers/readers.py", line 1661, in _make_engine
    self.handles = get_handle(
  File "/home/bruno/Documents/airflow_alura/venv/lib/python3.10/site-packages/pandas/io/common.py", line 716, in get_handle
    ioargs = _get_filepath_or_buffer(
  File "/home/bruno/Documents/airflow_alura/venv/lib/python3.10/site-packages/pandas/io/common.py", line 368, in _get_filepath_or_buffer
    with urlopen(req_info) as req:
  File "/home/bruno/Documents/airflow_alura/venv/lib/python3.10/site-packages/pandas/io/common.py", line 270, in urlopen
    return urllib.request.urlopen(*args, **kwargs)
  File "/usr/lib/python3.10/urllib/request.py", line 216, in urlopen
    return opener.open(url, data, timeout)
  File "/usr/lib/python3.10/urllib/request.py", line 525, in open
    response = meth(req, response)
  File "/usr/lib/python3.10/urllib/request.py", line 634, in http_response
    response = self.parent.error(
  File "/usr/lib/python3.10/urllib/request.py", line 563, in error
    return self._call_chain(*args)
  File "/usr/lib/python3.10/urllib/request.py", line 496, in _call_chain
    result = func(*args)
  File "/usr/lib/python3.10/urllib/request.py", line 643, in http_error_default
    raise HTTPError(req.full_url, code, msg, hdrs, fp)
urllib.error.HTTPError: HTTP Error 401: 
[2023-04-04 15:15:24,009] {taskinstance.py:1395} INFO - Marking task as FAILED. dag_id=dados_climaticos, task_id=extrai_dados, execution_date=20221017T000000, start_date=20230404T181523, end_date=20230404T181524
[2023-04-04 15:15:24,026] {standard_task_runner.py:92} ERROR - Failed to execute job 43 for task extrai_dados (HTTP Error 401: ; 8771)
[2023-04-04 15:15:24,062] {local_task_job.py:156} INFO - Task exited with return code 1
[2023-04-04 15:15:24,083] {local_task_job.py:273} INFO - 0 downstream tasks scheduled from follow-on schedule check
[2023-04-04 15:26:07,406] {taskinstance.py:1159} INFO - Dependencies all met for <TaskInstance: dados_climaticos.extrai_dados scheduled__2022-10-17T00:00:00+00:00 [queued]>
[2023-04-04 15:26:07,420] {taskinstance.py:1159} INFO - Dependencies all met for <TaskInstance: dados_climaticos.extrai_dados scheduled__2022-10-17T00:00:00+00:00 [queued]>
[2023-04-04 15:26:07,420] {taskinstance.py:1356} INFO - 
--------------------------------------------------------------------------------
[2023-04-04 15:26:07,420] {taskinstance.py:1357} INFO - Starting attempt 1 of 1
[2023-04-04 15:26:07,420] {taskinstance.py:1358} INFO - 
--------------------------------------------------------------------------------
[2023-04-04 15:26:07,442] {taskinstance.py:1377} INFO - Executing <Task(PythonOperator): extrai_dados> on 2022-10-17 00:00:00+00:00
[2023-04-04 15:26:07,445] {standard_task_runner.py:52} INFO - Started process 10855 to run task
[2023-04-04 15:26:07,447] {standard_task_runner.py:79} INFO - Running: ['airflow', 'tasks', 'run', 'dados_climaticos', 'extrai_dados', 'scheduled__2022-10-17T00:00:00+00:00', '--job-id', '46', '--raw', '--subdir', 'DAGS_FOLDER/dados_climaticos.py', '--cfg-path', '/tmp/tmpiys5kaqz', '--error-file', '/tmp/tmpvsw3kg_h']
[2023-04-04 15:26:07,448] {standard_task_runner.py:80} INFO - Job 46: Subtask extrai_dados
[2023-04-04 15:26:07,492] {task_command.py:370} INFO - Running <TaskInstance: dados_climaticos.extrai_dados scheduled__2022-10-17T00:00:00+00:00 [running]> on host bruno-H610M-H-DDR4
[2023-04-04 15:26:07,569] {taskinstance.py:1569} INFO - Exporting the following env vars:
AIRFLOW_CTX_DAG_OWNER=airflow
AIRFLOW_CTX_DAG_ID=dados_climaticos
AIRFLOW_CTX_TASK_ID=extrai_dados
AIRFLOW_CTX_EXECUTION_DATE=2022-10-17T00:00:00+00:00
AIRFLOW_CTX_TRY_NUMBER=1
AIRFLOW_CTX_DAG_RUN_ID=scheduled__2022-10-17T00:00:00+00:00
[2023-04-04 15:26:08,425] {python.py:173} INFO - Done. Returned value was: None
[2023-04-04 15:26:08,429] {taskinstance.py:1395} INFO - Marking task as SUCCESS. dag_id=dados_climaticos, task_id=extrai_dados, execution_date=20221017T000000, start_date=20230404T182607, end_date=20230404T182608
[2023-04-04 15:26:08,462] {local_task_job.py:156} INFO - Task exited with return code 0
[2023-04-04 15:26:08,487] {local_task_job.py:273} INFO - 0 downstream tasks scheduled from follow-on schedule check
