[2023-04-04 15:15:30,799] {taskinstance.py:1159} INFO - Dependencies all met for <TaskInstance: dados_climaticos.extrai_dados scheduled__2022-10-31T00:00:00+00:00 [queued]>
[2023-04-04 15:15:30,802] {taskinstance.py:1159} INFO - Dependencies all met for <TaskInstance: dados_climaticos.extrai_dados scheduled__2022-10-31T00:00:00+00:00 [queued]>
[2023-04-04 15:15:30,802] {taskinstance.py:1356} INFO - 
--------------------------------------------------------------------------------
[2023-04-04 15:15:30,802] {taskinstance.py:1357} INFO - Starting attempt 1 of 1
[2023-04-04 15:15:30,802] {taskinstance.py:1358} INFO - 
--------------------------------------------------------------------------------
[2023-04-04 15:15:30,823] {taskinstance.py:1377} INFO - Executing <Task(PythonOperator): extrai_dados> on 2022-10-31 00:00:00+00:00
[2023-04-04 15:15:30,825] {standard_task_runner.py:52} INFO - Started process 8821 to run task
[2023-04-04 15:15:30,827] {standard_task_runner.py:79} INFO - Running: ['airflow', 'tasks', 'run', 'dados_climaticos', 'extrai_dados', 'scheduled__2022-10-31T00:00:00+00:00', '--job-id', '47', '--raw', '--subdir', 'DAGS_FOLDER/dados_climaticos.py', '--cfg-path', '/tmp/tmph_g00wok', '--error-file', '/tmp/tmpxv5wbvow']
[2023-04-04 15:15:30,827] {standard_task_runner.py:80} INFO - Job 47: Subtask extrai_dados
[2023-04-04 15:15:30,872] {task_command.py:370} INFO - Running <TaskInstance: dados_climaticos.extrai_dados scheduled__2022-10-31T00:00:00+00:00 [running]> on host bruno-H610M-H-DDR4
[2023-04-04 15:15:30,926] {taskinstance.py:1569} INFO - Exporting the following env vars:
AIRFLOW_CTX_DAG_OWNER=airflow
AIRFLOW_CTX_DAG_ID=dados_climaticos
AIRFLOW_CTX_TASK_ID=extrai_dados
AIRFLOW_CTX_EXECUTION_DATE=2022-10-31T00:00:00+00:00
AIRFLOW_CTX_TRY_NUMBER=1
AIRFLOW_CTX_DAG_RUN_ID=scheduled__2022-10-31T00:00:00+00:00
[2023-04-04 15:15:31,618] {taskinstance.py:1889} ERROR - Task failed with exception
Traceback (most recent call last):
  File "/home/bruno/Documents/airflow_alura/venv/lib/python3.10/site-packages/airflow/operators/python.py", line 171, in execute
    return_value = self.execute_callable()
  File "/home/bruno/Documents/airflow_alura/venv/lib/python3.10/site-packages/airflow/operators/python.py", line 189, in execute_callable
    return self.python_callable(*self.op_args, **self.op_kwargs)
  File "/home/bruno/Documents/airflow_alura/dags/dados_climaticos.py", line 27, in extrai_dados
    dados = pd.read_csv(URL)
  File "/home/bruno/Documents/airflow_alura/venv/lib/python3.10/site-packages/pandas/io/parsers/readers.py", line 912, in read_csv
    return _read(filepath_or_buffer, kwds)
  File "/home/bruno/Documents/airflow_alura/venv/lib/python3.10/site-packages/pandas/io/parsers/readers.py", line 577, in _read
    parser = TextFileReader(filepath_or_buffer, **kwds)
  File "/home/bruno/Documents/airflow_alura/venv/lib/python3.10/site-packages/pandas/io/parsers/readers.py", line 1407, in __init__
    self._engine = self._make_engine(f, self.engine)
  File "/home/bruno/Documents/airflow_alura/venv/lib/python3.10/site-packages/pandas/io/parsers/readers.py", line 1661, in _make_engine
    self.handles = get_handle(
  File "/home/bruno/Documents/airflow_alura/venv/lib/python3.10/site-packages/pandas/io/common.py", line 716, in get_handle
    ioargs = _get_filepath_or_buffer(
  File "/home/bruno/Documents/airflow_alura/venv/lib/python3.10/site-packages/pandas/io/common.py", line 368, in _get_filepath_or_buffer
    with urlopen(req_info) as req:
  File "/home/bruno/Documents/airflow_alura/venv/lib/python3.10/site-packages/pandas/io/common.py", line 270, in urlopen
    return urllib.request.urlopen(*args, **kwargs)
  File "/usr/lib/python3.10/urllib/request.py", line 216, in urlopen
    return opener.open(url, data, timeout)
  File "/usr/lib/python3.10/urllib/request.py", line 525, in open
    response = meth(req, response)
  File "/usr/lib/python3.10/urllib/request.py", line 634, in http_response
    response = self.parent.error(
  File "/usr/lib/python3.10/urllib/request.py", line 563, in error
    return self._call_chain(*args)
  File "/usr/lib/python3.10/urllib/request.py", line 496, in _call_chain
    result = func(*args)
  File "/usr/lib/python3.10/urllib/request.py", line 643, in http_error_default
    raise HTTPError(req.full_url, code, msg, hdrs, fp)
urllib.error.HTTPError: HTTP Error 401: 
[2023-04-04 15:15:31,624] {taskinstance.py:1395} INFO - Marking task as FAILED. dag_id=dados_climaticos, task_id=extrai_dados, execution_date=20221031T000000, start_date=20230404T181530, end_date=20230404T181531
[2023-04-04 15:15:31,641] {standard_task_runner.py:92} ERROR - Failed to execute job 47 for task extrai_dados (HTTP Error 401: ; 8821)
[2023-04-04 15:15:31,682] {local_task_job.py:156} INFO - Task exited with return code 1
[2023-04-04 15:15:31,707] {local_task_job.py:273} INFO - 0 downstream tasks scheduled from follow-on schedule check
[2023-04-04 15:26:16,742] {taskinstance.py:1159} INFO - Dependencies all met for <TaskInstance: dados_climaticos.extrai_dados scheduled__2022-10-31T00:00:00+00:00 [queued]>
[2023-04-04 15:26:16,756] {taskinstance.py:1159} INFO - Dependencies all met for <TaskInstance: dados_climaticos.extrai_dados scheduled__2022-10-31T00:00:00+00:00 [queued]>
[2023-04-04 15:26:16,756] {taskinstance.py:1356} INFO - 
--------------------------------------------------------------------------------
[2023-04-04 15:26:16,756] {taskinstance.py:1357} INFO - Starting attempt 1 of 1
[2023-04-04 15:26:16,756] {taskinstance.py:1358} INFO - 
--------------------------------------------------------------------------------
[2023-04-04 15:26:16,778] {taskinstance.py:1377} INFO - Executing <Task(PythonOperator): extrai_dados> on 2022-10-31 00:00:00+00:00
[2023-04-04 15:26:16,781] {standard_task_runner.py:52} INFO - Started process 10915 to run task
[2023-04-04 15:26:16,783] {standard_task_runner.py:79} INFO - Running: ['airflow', 'tasks', 'run', 'dados_climaticos', 'extrai_dados', 'scheduled__2022-10-31T00:00:00+00:00', '--job-id', '51', '--raw', '--subdir', 'DAGS_FOLDER/dados_climaticos.py', '--cfg-path', '/tmp/tmpnsseoc7a', '--error-file', '/tmp/tmplbef32ic']
[2023-04-04 15:26:16,783] {standard_task_runner.py:80} INFO - Job 51: Subtask extrai_dados
[2023-04-04 15:26:16,823] {task_command.py:370} INFO - Running <TaskInstance: dados_climaticos.extrai_dados scheduled__2022-10-31T00:00:00+00:00 [running]> on host bruno-H610M-H-DDR4
[2023-04-04 15:26:16,876] {taskinstance.py:1569} INFO - Exporting the following env vars:
AIRFLOW_CTX_DAG_OWNER=airflow
AIRFLOW_CTX_DAG_ID=dados_climaticos
AIRFLOW_CTX_TASK_ID=extrai_dados
AIRFLOW_CTX_EXECUTION_DATE=2022-10-31T00:00:00+00:00
AIRFLOW_CTX_TRY_NUMBER=1
AIRFLOW_CTX_DAG_RUN_ID=scheduled__2022-10-31T00:00:00+00:00
[2023-04-04 15:26:17,795] {python.py:173} INFO - Done. Returned value was: None
[2023-04-04 15:26:17,799] {taskinstance.py:1395} INFO - Marking task as SUCCESS. dag_id=dados_climaticos, task_id=extrai_dados, execution_date=20221031T000000, start_date=20230404T182616, end_date=20230404T182617
[2023-04-04 15:26:17,837] {local_task_job.py:156} INFO - Task exited with return code 0
[2023-04-04 15:26:17,861] {local_task_job.py:273} INFO - 0 downstream tasks scheduled from follow-on schedule check
