[2023-04-04 14:49:49,090] {taskinstance.py:1159} INFO - Dependencies all met for <TaskInstance: dados_climaticos.extrai_dados scheduled__2022-08-29T00:00:00+00:00 [queued]>
[2023-04-04 14:49:49,093] {taskinstance.py:1159} INFO - Dependencies all met for <TaskInstance: dados_climaticos.extrai_dados scheduled__2022-08-29T00:00:00+00:00 [queued]>
[2023-04-04 14:49:49,094] {taskinstance.py:1356} INFO - 
--------------------------------------------------------------------------------
[2023-04-04 14:49:49,094] {taskinstance.py:1357} INFO - Starting attempt 1 of 1
[2023-04-04 14:49:49,094] {taskinstance.py:1358} INFO - 
--------------------------------------------------------------------------------
[2023-04-04 14:49:49,119] {taskinstance.py:1377} INFO - Executing <Task(PythonOperator): extrai_dados> on 2022-08-29 00:00:00+00:00
[2023-04-04 14:49:49,121] {standard_task_runner.py:52} INFO - Started process 14706 to run task
[2023-04-04 14:49:49,126] {standard_task_runner.py:79} INFO - Running: ['airflow', 'tasks', 'run', 'dados_climaticos', 'extrai_dados', 'scheduled__2022-08-29T00:00:00+00:00', '--job-id', '31', '--raw', '--subdir', 'DAGS_FOLDER/dados_climaticos.py', '--cfg-path', '/tmp/tmp14l0twfa', '--error-file', '/tmp/tmpjljv01an']
[2023-04-04 14:49:49,127] {standard_task_runner.py:80} INFO - Job 31: Subtask extrai_dados
[2023-04-04 14:49:49,187] {task_command.py:370} INFO - Running <TaskInstance: dados_climaticos.extrai_dados scheduled__2022-08-29T00:00:00+00:00 [running]> on host bruno-H610M-H-DDR4
[2023-04-04 14:49:49,240] {taskinstance.py:1569} INFO - Exporting the following env vars:
AIRFLOW_CTX_DAG_OWNER=airflow
AIRFLOW_CTX_DAG_ID=dados_climaticos
AIRFLOW_CTX_TASK_ID=extrai_dados
AIRFLOW_CTX_EXECUTION_DATE=2022-08-29T00:00:00+00:00
AIRFLOW_CTX_TRY_NUMBER=1
AIRFLOW_CTX_DAG_RUN_ID=scheduled__2022-08-29T00:00:00+00:00
[2023-04-04 14:49:49,914] {taskinstance.py:1889} ERROR - Task failed with exception
Traceback (most recent call last):
  File "/home/bruno/Documents/airflow_alura/venv/lib/python3.10/site-packages/airflow/operators/python.py", line 171, in execute
    return_value = self.execute_callable()
  File "/home/bruno/Documents/airflow_alura/venv/lib/python3.10/site-packages/airflow/operators/python.py", line 189, in execute_callable
    return self.python_callable(*self.op_args, **self.op_kwargs)
  File "/home/bruno/Documents/airflow_alura/dags/dados_climaticos.py", line 27, in extrai_dados
    dados = pd.read_csv(URL)
  File "/home/bruno/Documents/airflow_alura/venv/lib/python3.10/site-packages/pandas/io/parsers/readers.py", line 912, in read_csv
    return _read(filepath_or_buffer, kwds)
  File "/home/bruno/Documents/airflow_alura/venv/lib/python3.10/site-packages/pandas/io/parsers/readers.py", line 577, in _read
    parser = TextFileReader(filepath_or_buffer, **kwds)
  File "/home/bruno/Documents/airflow_alura/venv/lib/python3.10/site-packages/pandas/io/parsers/readers.py", line 1407, in __init__
    self._engine = self._make_engine(f, self.engine)
  File "/home/bruno/Documents/airflow_alura/venv/lib/python3.10/site-packages/pandas/io/parsers/readers.py", line 1661, in _make_engine
    self.handles = get_handle(
  File "/home/bruno/Documents/airflow_alura/venv/lib/python3.10/site-packages/pandas/io/common.py", line 716, in get_handle
    ioargs = _get_filepath_or_buffer(
  File "/home/bruno/Documents/airflow_alura/venv/lib/python3.10/site-packages/pandas/io/common.py", line 368, in _get_filepath_or_buffer
    with urlopen(req_info) as req:
  File "/home/bruno/Documents/airflow_alura/venv/lib/python3.10/site-packages/pandas/io/common.py", line 270, in urlopen
    return urllib.request.urlopen(*args, **kwargs)
  File "/usr/lib/python3.10/urllib/request.py", line 216, in urlopen
    return opener.open(url, data, timeout)
  File "/usr/lib/python3.10/urllib/request.py", line 525, in open
    response = meth(req, response)
  File "/usr/lib/python3.10/urllib/request.py", line 634, in http_response
    response = self.parent.error(
  File "/usr/lib/python3.10/urllib/request.py", line 563, in error
    return self._call_chain(*args)
  File "/usr/lib/python3.10/urllib/request.py", line 496, in _call_chain
    result = func(*args)
  File "/usr/lib/python3.10/urllib/request.py", line 643, in http_error_default
    raise HTTPError(req.full_url, code, msg, hdrs, fp)
urllib.error.HTTPError: HTTP Error 401: 
[2023-04-04 14:49:49,925] {taskinstance.py:1395} INFO - Marking task as FAILED. dag_id=dados_climaticos, task_id=extrai_dados, execution_date=20220829T000000, start_date=20230404T174949, end_date=20230404T174949
[2023-04-04 14:49:49,953] {standard_task_runner.py:92} ERROR - Failed to execute job 31 for task extrai_dados (HTTP Error 401: ; 14706)
[2023-04-04 14:49:49,979] {local_task_job.py:156} INFO - Task exited with return code 1
[2023-04-04 14:49:49,996] {local_task_job.py:273} INFO - 0 downstream tasks scheduled from follow-on schedule check
[2023-04-04 15:18:26,827] {taskinstance.py:1159} INFO - Dependencies all met for <TaskInstance: dados_climaticos.extrai_dados scheduled__2022-08-29T00:00:00+00:00 [queued]>
[2023-04-04 15:18:26,841] {taskinstance.py:1159} INFO - Dependencies all met for <TaskInstance: dados_climaticos.extrai_dados scheduled__2022-08-29T00:00:00+00:00 [queued]>
[2023-04-04 15:18:26,841] {taskinstance.py:1356} INFO - 
--------------------------------------------------------------------------------
[2023-04-04 15:18:26,841] {taskinstance.py:1357} INFO - Starting attempt 1 of 1
[2023-04-04 15:18:26,841] {taskinstance.py:1358} INFO - 
--------------------------------------------------------------------------------
[2023-04-04 15:18:26,862] {taskinstance.py:1377} INFO - Executing <Task(PythonOperator): extrai_dados> on 2022-08-29 00:00:00+00:00
[2023-04-04 15:18:26,864] {standard_task_runner.py:52} INFO - Started process 9555 to run task
[2023-04-04 15:18:26,868] {standard_task_runner.py:79} INFO - Running: ['airflow', 'tasks', 'run', 'dados_climaticos', 'extrai_dados', 'scheduled__2022-08-29T00:00:00+00:00', '--job-id', '33', '--raw', '--subdir', 'DAGS_FOLDER/dados_climaticos.py', '--cfg-path', '/tmp/tmp50_aeriq', '--error-file', '/tmp/tmpr4lfbi2r']
[2023-04-04 15:18:26,869] {standard_task_runner.py:80} INFO - Job 33: Subtask extrai_dados
[2023-04-04 15:18:26,912] {task_command.py:370} INFO - Running <TaskInstance: dados_climaticos.extrai_dados scheduled__2022-08-29T00:00:00+00:00 [running]> on host bruno-H610M-H-DDR4
[2023-04-04 15:18:26,962] {taskinstance.py:1569} INFO - Exporting the following env vars:
AIRFLOW_CTX_DAG_OWNER=airflow
AIRFLOW_CTX_DAG_ID=dados_climaticos
AIRFLOW_CTX_TASK_ID=extrai_dados
AIRFLOW_CTX_EXECUTION_DATE=2022-08-29T00:00:00+00:00
AIRFLOW_CTX_TRY_NUMBER=1
AIRFLOW_CTX_DAG_RUN_ID=scheduled__2022-08-29T00:00:00+00:00
[2023-04-04 15:18:27,791] {taskinstance.py:1889} ERROR - Task failed with exception
Traceback (most recent call last):
  File "/home/bruno/Documents/airflow_alura/venv/lib/python3.10/site-packages/airflow/operators/python.py", line 171, in execute
    return_value = self.execute_callable()
  File "/home/bruno/Documents/airflow_alura/venv/lib/python3.10/site-packages/airflow/operators/python.py", line 189, in execute_callable
    return self.python_callable(*self.op_args, **self.op_kwargs)
  File "/home/bruno/Documents/airflow_alura/dags/dados_climaticos.py", line 32, in extrai_dados
    dados[['datetime', 'tempmin', 'temp', 'tempax']].to_csv(
  File "/home/bruno/Documents/airflow_alura/venv/lib/python3.10/site-packages/pandas/core/frame.py", line 3766, in __getitem__
    indexer = self.columns._get_indexer_strict(key, "columns")[1]
  File "/home/bruno/Documents/airflow_alura/venv/lib/python3.10/site-packages/pandas/core/indexes/base.py", line 5876, in _get_indexer_strict
    self._raise_if_missing(keyarr, indexer, axis_name)
  File "/home/bruno/Documents/airflow_alura/venv/lib/python3.10/site-packages/pandas/core/indexes/base.py", line 5938, in _raise_if_missing
    raise KeyError(f"{not_found} not in index")
KeyError: "['tempax'] not in index"
[2023-04-04 15:18:27,795] {taskinstance.py:1395} INFO - Marking task as FAILED. dag_id=dados_climaticos, task_id=extrai_dados, execution_date=20220829T000000, start_date=20230404T181826, end_date=20230404T181827
[2023-04-04 15:18:27,821] {standard_task_runner.py:92} ERROR - Failed to execute job 33 for task extrai_dados ("['tempax'] not in index"; 9555)
[2023-04-04 15:18:27,841] {local_task_job.py:156} INFO - Task exited with return code 1
[2023-04-04 15:18:27,855] {local_task_job.py:273} INFO - 0 downstream tasks scheduled from follow-on schedule check
[2023-04-04 15:20:42,507] {taskinstance.py:1159} INFO - Dependencies all met for <TaskInstance: dados_climaticos.extrai_dados scheduled__2022-08-29T00:00:00+00:00 [queued]>
[2023-04-04 15:20:42,521] {taskinstance.py:1159} INFO - Dependencies all met for <TaskInstance: dados_climaticos.extrai_dados scheduled__2022-08-29T00:00:00+00:00 [queued]>
[2023-04-04 15:20:42,521] {taskinstance.py:1356} INFO - 
--------------------------------------------------------------------------------
[2023-04-04 15:20:42,521] {taskinstance.py:1357} INFO - Starting attempt 1 of 1
[2023-04-04 15:20:42,521] {taskinstance.py:1358} INFO - 
--------------------------------------------------------------------------------
[2023-04-04 15:20:42,542] {taskinstance.py:1377} INFO - Executing <Task(PythonOperator): extrai_dados> on 2022-08-29 00:00:00+00:00
[2023-04-04 15:20:42,545] {standard_task_runner.py:52} INFO - Started process 9955 to run task
[2023-04-04 15:20:42,547] {standard_task_runner.py:79} INFO - Running: ['airflow', 'tasks', 'run', 'dados_climaticos', 'extrai_dados', 'scheduled__2022-08-29T00:00:00+00:00', '--job-id', '33', '--raw', '--subdir', 'DAGS_FOLDER/dados_climaticos.py', '--cfg-path', '/tmp/tmpnl14a8fm', '--error-file', '/tmp/tmpiqos0zut']
[2023-04-04 15:20:42,548] {standard_task_runner.py:80} INFO - Job 33: Subtask extrai_dados
[2023-04-04 15:20:42,593] {task_command.py:370} INFO - Running <TaskInstance: dados_climaticos.extrai_dados scheduled__2022-08-29T00:00:00+00:00 [running]> on host bruno-H610M-H-DDR4
[2023-04-04 15:20:42,644] {taskinstance.py:1569} INFO - Exporting the following env vars:
AIRFLOW_CTX_DAG_OWNER=airflow
AIRFLOW_CTX_DAG_ID=dados_climaticos
AIRFLOW_CTX_TASK_ID=extrai_dados
AIRFLOW_CTX_EXECUTION_DATE=2022-08-29T00:00:00+00:00
AIRFLOW_CTX_TRY_NUMBER=1
AIRFLOW_CTX_DAG_RUN_ID=scheduled__2022-08-29T00:00:00+00:00
[2023-04-04 15:20:43,381] {taskinstance.py:1889} ERROR - Task failed with exception
Traceback (most recent call last):
  File "/home/bruno/Documents/airflow_alura/venv/lib/python3.10/site-packages/airflow/operators/python.py", line 171, in execute
    return_value = self.execute_callable()
  File "/home/bruno/Documents/airflow_alura/venv/lib/python3.10/site-packages/airflow/operators/python.py", line 189, in execute_callable
    return self.python_callable(*self.op_args, **self.op_kwargs)
  File "/home/bruno/Documents/airflow_alura/dags/dados_climaticos.py", line 32, in extrai_dados
    dados[['datetime', 'tempmin', 'temp', 'tempax']].to_csv(
  File "/home/bruno/Documents/airflow_alura/venv/lib/python3.10/site-packages/pandas/core/frame.py", line 3766, in __getitem__
    indexer = self.columns._get_indexer_strict(key, "columns")[1]
  File "/home/bruno/Documents/airflow_alura/venv/lib/python3.10/site-packages/pandas/core/indexes/base.py", line 5876, in _get_indexer_strict
    self._raise_if_missing(keyarr, indexer, axis_name)
  File "/home/bruno/Documents/airflow_alura/venv/lib/python3.10/site-packages/pandas/core/indexes/base.py", line 5938, in _raise_if_missing
    raise KeyError(f"{not_found} not in index")
KeyError: "['tempax'] not in index"
[2023-04-04 15:20:43,384] {taskinstance.py:1395} INFO - Marking task as FAILED. dag_id=dados_climaticos, task_id=extrai_dados, execution_date=20220829T000000, start_date=20230404T182042, end_date=20230404T182043
[2023-04-04 15:20:43,407] {standard_task_runner.py:92} ERROR - Failed to execute job 33 for task extrai_dados ("['tempax'] not in index"; 9955)
[2023-04-04 15:20:43,441] {local_task_job.py:156} INFO - Task exited with return code 1
[2023-04-04 15:20:43,465] {local_task_job.py:273} INFO - 0 downstream tasks scheduled from follow-on schedule check
[2023-04-04 15:22:26,511] {taskinstance.py:1159} INFO - Dependencies all met for <TaskInstance: dados_climaticos.extrai_dados scheduled__2022-08-29T00:00:00+00:00 [queued]>
[2023-04-04 15:22:26,524] {taskinstance.py:1159} INFO - Dependencies all met for <TaskInstance: dados_climaticos.extrai_dados scheduled__2022-08-29T00:00:00+00:00 [queued]>
[2023-04-04 15:22:26,525] {taskinstance.py:1356} INFO - 
--------------------------------------------------------------------------------
[2023-04-04 15:22:26,525] {taskinstance.py:1357} INFO - Starting attempt 1 of 1
[2023-04-04 15:22:26,525] {taskinstance.py:1358} INFO - 
--------------------------------------------------------------------------------
[2023-04-04 15:22:26,546] {taskinstance.py:1377} INFO - Executing <Task(PythonOperator): extrai_dados> on 2022-08-29 00:00:00+00:00
[2023-04-04 15:22:26,548] {standard_task_runner.py:52} INFO - Started process 10231 to run task
[2023-04-04 15:22:26,551] {standard_task_runner.py:79} INFO - Running: ['airflow', 'tasks', 'run', 'dados_climaticos', 'extrai_dados', 'scheduled__2022-08-29T00:00:00+00:00', '--job-id', '33', '--raw', '--subdir', 'DAGS_FOLDER/dados_climaticos.py', '--cfg-path', '/tmp/tmpdppmjdeq', '--error-file', '/tmp/tmp2geb6hhb']
[2023-04-04 15:22:26,551] {standard_task_runner.py:80} INFO - Job 33: Subtask extrai_dados
[2023-04-04 15:22:26,590] {task_command.py:370} INFO - Running <TaskInstance: dados_climaticos.extrai_dados scheduled__2022-08-29T00:00:00+00:00 [running]> on host bruno-H610M-H-DDR4
[2023-04-04 15:22:26,642] {taskinstance.py:1569} INFO - Exporting the following env vars:
AIRFLOW_CTX_DAG_OWNER=airflow
AIRFLOW_CTX_DAG_ID=dados_climaticos
AIRFLOW_CTX_TASK_ID=extrai_dados
AIRFLOW_CTX_EXECUTION_DATE=2022-08-29T00:00:00+00:00
AIRFLOW_CTX_TRY_NUMBER=1
AIRFLOW_CTX_DAG_RUN_ID=scheduled__2022-08-29T00:00:00+00:00
[2023-04-04 15:22:27,430] {taskinstance.py:1889} ERROR - Task failed with exception
Traceback (most recent call last):
  File "/home/bruno/Documents/airflow_alura/venv/lib/python3.10/site-packages/airflow/operators/python.py", line 171, in execute
    return_value = self.execute_callable()
  File "/home/bruno/Documents/airflow_alura/venv/lib/python3.10/site-packages/airflow/operators/python.py", line 189, in execute_callable
    return self.python_callable(*self.op_args, **self.op_kwargs)
  File "/home/bruno/Documents/airflow_alura/dags/dados_climaticos.py", line 32, in extrai_dados
    dados[['datetime', 'tempmin', 'temp', 'tempax']].to_csv(
  File "/home/bruno/Documents/airflow_alura/venv/lib/python3.10/site-packages/pandas/core/frame.py", line 3766, in __getitem__
    indexer = self.columns._get_indexer_strict(key, "columns")[1]
  File "/home/bruno/Documents/airflow_alura/venv/lib/python3.10/site-packages/pandas/core/indexes/base.py", line 5876, in _get_indexer_strict
    self._raise_if_missing(keyarr, indexer, axis_name)
  File "/home/bruno/Documents/airflow_alura/venv/lib/python3.10/site-packages/pandas/core/indexes/base.py", line 5938, in _raise_if_missing
    raise KeyError(f"{not_found} not in index")
KeyError: "['tempax'] not in index"
[2023-04-04 15:22:27,436] {taskinstance.py:1395} INFO - Marking task as FAILED. dag_id=dados_climaticos, task_id=extrai_dados, execution_date=20220829T000000, start_date=20230404T182226, end_date=20230404T182227
[2023-04-04 15:22:27,457] {standard_task_runner.py:92} ERROR - Failed to execute job 33 for task extrai_dados ("['tempax'] not in index"; 10231)
[2023-04-04 15:22:27,484] {local_task_job.py:156} INFO - Task exited with return code 1
[2023-04-04 15:22:27,504] {local_task_job.py:273} INFO - 0 downstream tasks scheduled from follow-on schedule check
[2023-04-04 15:25:42,463] {taskinstance.py:1159} INFO - Dependencies all met for <TaskInstance: dados_climaticos.extrai_dados scheduled__2022-08-29T00:00:00+00:00 [queued]>
[2023-04-04 15:25:42,476] {taskinstance.py:1159} INFO - Dependencies all met for <TaskInstance: dados_climaticos.extrai_dados scheduled__2022-08-29T00:00:00+00:00 [queued]>
[2023-04-04 15:25:42,477] {taskinstance.py:1356} INFO - 
--------------------------------------------------------------------------------
[2023-04-04 15:25:42,477] {taskinstance.py:1357} INFO - Starting attempt 1 of 1
[2023-04-04 15:25:42,477] {taskinstance.py:1358} INFO - 
--------------------------------------------------------------------------------
[2023-04-04 15:25:42,498] {taskinstance.py:1377} INFO - Executing <Task(PythonOperator): extrai_dados> on 2022-08-29 00:00:00+00:00
[2023-04-04 15:25:42,501] {standard_task_runner.py:52} INFO - Started process 10697 to run task
[2023-04-04 15:25:42,504] {standard_task_runner.py:79} INFO - Running: ['airflow', 'tasks', 'run', 'dados_climaticos', 'extrai_dados', 'scheduled__2022-08-29T00:00:00+00:00', '--job-id', '33', '--raw', '--subdir', 'DAGS_FOLDER/dados_climaticos.py', '--cfg-path', '/tmp/tmpf1authd0', '--error-file', '/tmp/tmpy7ff58nc']
[2023-04-04 15:25:42,504] {standard_task_runner.py:80} INFO - Job 33: Subtask extrai_dados
[2023-04-04 15:25:42,546] {task_command.py:370} INFO - Running <TaskInstance: dados_climaticos.extrai_dados scheduled__2022-08-29T00:00:00+00:00 [running]> on host bruno-H610M-H-DDR4
[2023-04-04 15:25:42,606] {taskinstance.py:1569} INFO - Exporting the following env vars:
AIRFLOW_CTX_DAG_OWNER=airflow
AIRFLOW_CTX_DAG_ID=dados_climaticos
AIRFLOW_CTX_TASK_ID=extrai_dados
AIRFLOW_CTX_EXECUTION_DATE=2022-08-29T00:00:00+00:00
AIRFLOW_CTX_TRY_NUMBER=1
AIRFLOW_CTX_DAG_RUN_ID=scheduled__2022-08-29T00:00:00+00:00
[2023-04-04 15:25:43,376] {python.py:173} INFO - Done. Returned value was: None
[2023-04-04 15:25:43,380] {taskinstance.py:1395} INFO - Marking task as SUCCESS. dag_id=dados_climaticos, task_id=extrai_dados, execution_date=20220829T000000, start_date=20230404T182542, end_date=20230404T182543
[2023-04-04 15:25:43,477] {local_task_job.py:156} INFO - Task exited with return code 0
[2023-04-04 15:25:43,502] {local_task_job.py:273} INFO - 0 downstream tasks scheduled from follow-on schedule check
