[2023-04-04 14:49:56,814] {taskinstance.py:1159} INFO - Dependencies all met for <TaskInstance: dados_climaticos.extrai_dados scheduled__2022-09-12T00:00:00+00:00 [queued]>
[2023-04-04 14:49:56,817] {taskinstance.py:1159} INFO - Dependencies all met for <TaskInstance: dados_climaticos.extrai_dados scheduled__2022-09-12T00:00:00+00:00 [queued]>
[2023-04-04 14:49:56,817] {taskinstance.py:1356} INFO - 
--------------------------------------------------------------------------------
[2023-04-04 14:49:56,817] {taskinstance.py:1357} INFO - Starting attempt 1 of 1
[2023-04-04 14:49:56,817] {taskinstance.py:1358} INFO - 
--------------------------------------------------------------------------------
[2023-04-04 14:49:56,839] {taskinstance.py:1377} INFO - Executing <Task(PythonOperator): extrai_dados> on 2022-09-12 00:00:00+00:00
[2023-04-04 14:49:56,841] {standard_task_runner.py:52} INFO - Started process 14762 to run task
[2023-04-04 14:49:56,843] {standard_task_runner.py:79} INFO - Running: ['airflow', 'tasks', 'run', 'dados_climaticos', 'extrai_dados', 'scheduled__2022-09-12T00:00:00+00:00', '--job-id', '35', '--raw', '--subdir', 'DAGS_FOLDER/dados_climaticos.py', '--cfg-path', '/tmp/tmp_4t_myv3', '--error-file', '/tmp/tmpteoiwbtx']
[2023-04-04 14:49:56,844] {standard_task_runner.py:80} INFO - Job 35: Subtask extrai_dados
[2023-04-04 14:49:56,881] {task_command.py:370} INFO - Running <TaskInstance: dados_climaticos.extrai_dados scheduled__2022-09-12T00:00:00+00:00 [running]> on host bruno-H610M-H-DDR4
[2023-04-04 14:49:56,924] {taskinstance.py:1569} INFO - Exporting the following env vars:
AIRFLOW_CTX_DAG_OWNER=airflow
AIRFLOW_CTX_DAG_ID=dados_climaticos
AIRFLOW_CTX_TASK_ID=extrai_dados
AIRFLOW_CTX_EXECUTION_DATE=2022-09-12T00:00:00+00:00
AIRFLOW_CTX_TRY_NUMBER=1
AIRFLOW_CTX_DAG_RUN_ID=scheduled__2022-09-12T00:00:00+00:00
[2023-04-04 14:49:57,595] {taskinstance.py:1889} ERROR - Task failed with exception
Traceback (most recent call last):
  File "/home/bruno/Documents/airflow_alura/venv/lib/python3.10/site-packages/airflow/operators/python.py", line 171, in execute
    return_value = self.execute_callable()
  File "/home/bruno/Documents/airflow_alura/venv/lib/python3.10/site-packages/airflow/operators/python.py", line 189, in execute_callable
    return self.python_callable(*self.op_args, **self.op_kwargs)
  File "/home/bruno/Documents/airflow_alura/dags/dados_climaticos.py", line 27, in extrai_dados
    dados = pd.read_csv(URL)
  File "/home/bruno/Documents/airflow_alura/venv/lib/python3.10/site-packages/pandas/io/parsers/readers.py", line 912, in read_csv
    return _read(filepath_or_buffer, kwds)
  File "/home/bruno/Documents/airflow_alura/venv/lib/python3.10/site-packages/pandas/io/parsers/readers.py", line 577, in _read
    parser = TextFileReader(filepath_or_buffer, **kwds)
  File "/home/bruno/Documents/airflow_alura/venv/lib/python3.10/site-packages/pandas/io/parsers/readers.py", line 1407, in __init__
    self._engine = self._make_engine(f, self.engine)
  File "/home/bruno/Documents/airflow_alura/venv/lib/python3.10/site-packages/pandas/io/parsers/readers.py", line 1661, in _make_engine
    self.handles = get_handle(
  File "/home/bruno/Documents/airflow_alura/venv/lib/python3.10/site-packages/pandas/io/common.py", line 716, in get_handle
    ioargs = _get_filepath_or_buffer(
  File "/home/bruno/Documents/airflow_alura/venv/lib/python3.10/site-packages/pandas/io/common.py", line 368, in _get_filepath_or_buffer
    with urlopen(req_info) as req:
  File "/home/bruno/Documents/airflow_alura/venv/lib/python3.10/site-packages/pandas/io/common.py", line 270, in urlopen
    return urllib.request.urlopen(*args, **kwargs)
  File "/usr/lib/python3.10/urllib/request.py", line 216, in urlopen
    return opener.open(url, data, timeout)
  File "/usr/lib/python3.10/urllib/request.py", line 525, in open
    response = meth(req, response)
  File "/usr/lib/python3.10/urllib/request.py", line 634, in http_response
    response = self.parent.error(
  File "/usr/lib/python3.10/urllib/request.py", line 563, in error
    return self._call_chain(*args)
  File "/usr/lib/python3.10/urllib/request.py", line 496, in _call_chain
    result = func(*args)
  File "/usr/lib/python3.10/urllib/request.py", line 643, in http_error_default
    raise HTTPError(req.full_url, code, msg, hdrs, fp)
urllib.error.HTTPError: HTTP Error 401: 
[2023-04-04 14:49:57,606] {taskinstance.py:1395} INFO - Marking task as FAILED. dag_id=dados_climaticos, task_id=extrai_dados, execution_date=20220912T000000, start_date=20230404T174956, end_date=20230404T174957
[2023-04-04 14:49:57,633] {standard_task_runner.py:92} ERROR - Failed to execute job 35 for task extrai_dados (HTTP Error 401: ; 14762)
[2023-04-04 14:49:57,657] {local_task_job.py:156} INFO - Task exited with return code 1
[2023-04-04 14:49:57,675] {local_task_job.py:273} INFO - 0 downstream tasks scheduled from follow-on schedule check
[2023-04-04 15:18:34,844] {taskinstance.py:1159} INFO - Dependencies all met for <TaskInstance: dados_climaticos.extrai_dados scheduled__2022-09-12T00:00:00+00:00 [queued]>
[2023-04-04 15:18:34,858] {taskinstance.py:1159} INFO - Dependencies all met for <TaskInstance: dados_climaticos.extrai_dados scheduled__2022-09-12T00:00:00+00:00 [queued]>
[2023-04-04 15:18:34,858] {taskinstance.py:1356} INFO - 
--------------------------------------------------------------------------------
[2023-04-04 15:18:34,858] {taskinstance.py:1357} INFO - Starting attempt 1 of 1
[2023-04-04 15:18:34,859] {taskinstance.py:1358} INFO - 
--------------------------------------------------------------------------------
[2023-04-04 15:18:34,881] {taskinstance.py:1377} INFO - Executing <Task(PythonOperator): extrai_dados> on 2022-09-12 00:00:00+00:00
[2023-04-04 15:18:34,885] {standard_task_runner.py:52} INFO - Started process 9605 to run task
[2023-04-04 15:18:34,891] {standard_task_runner.py:79} INFO - Running: ['airflow', 'tasks', 'run', 'dados_climaticos', 'extrai_dados', 'scheduled__2022-09-12T00:00:00+00:00', '--job-id', '37', '--raw', '--subdir', 'DAGS_FOLDER/dados_climaticos.py', '--cfg-path', '/tmp/tmpiha2mu6i', '--error-file', '/tmp/tmpb8utha30']
[2023-04-04 15:18:34,893] {standard_task_runner.py:80} INFO - Job 37: Subtask extrai_dados
[2023-04-04 15:18:34,953] {task_command.py:370} INFO - Running <TaskInstance: dados_climaticos.extrai_dados scheduled__2022-09-12T00:00:00+00:00 [running]> on host bruno-H610M-H-DDR4
[2023-04-04 15:18:35,002] {taskinstance.py:1569} INFO - Exporting the following env vars:
AIRFLOW_CTX_DAG_OWNER=airflow
AIRFLOW_CTX_DAG_ID=dados_climaticos
AIRFLOW_CTX_TASK_ID=extrai_dados
AIRFLOW_CTX_EXECUTION_DATE=2022-09-12T00:00:00+00:00
AIRFLOW_CTX_TRY_NUMBER=1
AIRFLOW_CTX_DAG_RUN_ID=scheduled__2022-09-12T00:00:00+00:00
[2023-04-04 15:18:35,813] {taskinstance.py:1889} ERROR - Task failed with exception
Traceback (most recent call last):
  File "/home/bruno/Documents/airflow_alura/venv/lib/python3.10/site-packages/airflow/operators/python.py", line 171, in execute
    return_value = self.execute_callable()
  File "/home/bruno/Documents/airflow_alura/venv/lib/python3.10/site-packages/airflow/operators/python.py", line 189, in execute_callable
    return self.python_callable(*self.op_args, **self.op_kwargs)
  File "/home/bruno/Documents/airflow_alura/dags/dados_climaticos.py", line 32, in extrai_dados
    dados[['datetime', 'tempmin', 'temp', 'tempax']].to_csv(
  File "/home/bruno/Documents/airflow_alura/venv/lib/python3.10/site-packages/pandas/core/frame.py", line 3766, in __getitem__
    indexer = self.columns._get_indexer_strict(key, "columns")[1]
  File "/home/bruno/Documents/airflow_alura/venv/lib/python3.10/site-packages/pandas/core/indexes/base.py", line 5876, in _get_indexer_strict
    self._raise_if_missing(keyarr, indexer, axis_name)
  File "/home/bruno/Documents/airflow_alura/venv/lib/python3.10/site-packages/pandas/core/indexes/base.py", line 5938, in _raise_if_missing
    raise KeyError(f"{not_found} not in index")
KeyError: "['tempax'] not in index"
[2023-04-04 15:18:35,826] {taskinstance.py:1395} INFO - Marking task as FAILED. dag_id=dados_climaticos, task_id=extrai_dados, execution_date=20220912T000000, start_date=20230404T181834, end_date=20230404T181835
[2023-04-04 15:18:35,841] {standard_task_runner.py:92} ERROR - Failed to execute job 37 for task extrai_dados ("['tempax'] not in index"; 9605)
[2023-04-04 15:18:35,863] {local_task_job.py:156} INFO - Task exited with return code 1
[2023-04-04 15:18:35,873] {local_task_job.py:273} INFO - 0 downstream tasks scheduled from follow-on schedule check
[2023-04-04 15:20:50,407] {taskinstance.py:1159} INFO - Dependencies all met for <TaskInstance: dados_climaticos.extrai_dados scheduled__2022-09-12T00:00:00+00:00 [queued]>
[2023-04-04 15:20:50,421] {taskinstance.py:1159} INFO - Dependencies all met for <TaskInstance: dados_climaticos.extrai_dados scheduled__2022-09-12T00:00:00+00:00 [queued]>
[2023-04-04 15:20:50,421] {taskinstance.py:1356} INFO - 
--------------------------------------------------------------------------------
[2023-04-04 15:20:50,421] {taskinstance.py:1357} INFO - Starting attempt 1 of 1
[2023-04-04 15:20:50,421] {taskinstance.py:1358} INFO - 
--------------------------------------------------------------------------------
[2023-04-04 15:20:50,442] {taskinstance.py:1377} INFO - Executing <Task(PythonOperator): extrai_dados> on 2022-09-12 00:00:00+00:00
[2023-04-04 15:20:50,445] {standard_task_runner.py:52} INFO - Started process 10000 to run task
[2023-04-04 15:20:50,448] {standard_task_runner.py:79} INFO - Running: ['airflow', 'tasks', 'run', 'dados_climaticos', 'extrai_dados', 'scheduled__2022-09-12T00:00:00+00:00', '--job-id', '37', '--raw', '--subdir', 'DAGS_FOLDER/dados_climaticos.py', '--cfg-path', '/tmp/tmpm39pnhh6', '--error-file', '/tmp/tmpx0r4zg2z']
[2023-04-04 15:20:50,448] {standard_task_runner.py:80} INFO - Job 37: Subtask extrai_dados
[2023-04-04 15:20:50,501] {task_command.py:370} INFO - Running <TaskInstance: dados_climaticos.extrai_dados scheduled__2022-09-12T00:00:00+00:00 [running]> on host bruno-H610M-H-DDR4
[2023-04-04 15:20:50,560] {taskinstance.py:1569} INFO - Exporting the following env vars:
AIRFLOW_CTX_DAG_OWNER=airflow
AIRFLOW_CTX_DAG_ID=dados_climaticos
AIRFLOW_CTX_TASK_ID=extrai_dados
AIRFLOW_CTX_EXECUTION_DATE=2022-09-12T00:00:00+00:00
AIRFLOW_CTX_TRY_NUMBER=1
AIRFLOW_CTX_DAG_RUN_ID=scheduled__2022-09-12T00:00:00+00:00
[2023-04-04 15:20:51,340] {taskinstance.py:1889} ERROR - Task failed with exception
Traceback (most recent call last):
  File "/home/bruno/Documents/airflow_alura/venv/lib/python3.10/site-packages/airflow/operators/python.py", line 171, in execute
    return_value = self.execute_callable()
  File "/home/bruno/Documents/airflow_alura/venv/lib/python3.10/site-packages/airflow/operators/python.py", line 189, in execute_callable
    return self.python_callable(*self.op_args, **self.op_kwargs)
  File "/home/bruno/Documents/airflow_alura/dags/dados_climaticos.py", line 32, in extrai_dados
    dados[['datetime', 'tempmin', 'temp', 'tempax']].to_csv(
  File "/home/bruno/Documents/airflow_alura/venv/lib/python3.10/site-packages/pandas/core/frame.py", line 3766, in __getitem__
    indexer = self.columns._get_indexer_strict(key, "columns")[1]
  File "/home/bruno/Documents/airflow_alura/venv/lib/python3.10/site-packages/pandas/core/indexes/base.py", line 5876, in _get_indexer_strict
    self._raise_if_missing(keyarr, indexer, axis_name)
  File "/home/bruno/Documents/airflow_alura/venv/lib/python3.10/site-packages/pandas/core/indexes/base.py", line 5938, in _raise_if_missing
    raise KeyError(f"{not_found} not in index")
KeyError: "['tempax'] not in index"
[2023-04-04 15:20:51,346] {taskinstance.py:1395} INFO - Marking task as FAILED. dag_id=dados_climaticos, task_id=extrai_dados, execution_date=20220912T000000, start_date=20230404T182050, end_date=20230404T182051
[2023-04-04 15:20:51,366] {standard_task_runner.py:92} ERROR - Failed to execute job 37 for task extrai_dados ("['tempax'] not in index"; 10000)
[2023-04-04 15:20:51,382] {local_task_job.py:156} INFO - Task exited with return code 1
[2023-04-04 15:20:51,423] {local_task_job.py:273} INFO - 0 downstream tasks scheduled from follow-on schedule check
[2023-04-04 15:20:51,431] {dagrun.py:547} ERROR - Marking run <DagRun dados_climaticos @ 2022-09-12 00:00:00+00:00: scheduled__2022-09-12T00:00:00+00:00, externally triggered: False> failed
[2023-04-04 15:20:51,432] {dagrun.py:607} INFO - DagRun Finished: dag_id=dados_climaticos, execution_date=2022-09-12 00:00:00+00:00, run_id=scheduled__2022-09-12T00:00:00+00:00, run_start_date=2023-04-04 18:20:47.091653+00:00, run_end_date=2023-04-04 18:20:51.432095+00:00, run_duration=4.340442, state=failed, external_trigger=False, run_type=scheduled, data_interval_start=2022-09-12 00:00:00+00:00, data_interval_end=2022-09-19 00:00:00+00:00, dag_hash=2e660890e4f3cfd24fe1440c24398a9f
[2023-04-04 15:22:34,376] {taskinstance.py:1159} INFO - Dependencies all met for <TaskInstance: dados_climaticos.extrai_dados scheduled__2022-09-12T00:00:00+00:00 [queued]>
[2023-04-04 15:22:34,390] {taskinstance.py:1159} INFO - Dependencies all met for <TaskInstance: dados_climaticos.extrai_dados scheduled__2022-09-12T00:00:00+00:00 [queued]>
[2023-04-04 15:22:34,390] {taskinstance.py:1356} INFO - 
--------------------------------------------------------------------------------
[2023-04-04 15:22:34,390] {taskinstance.py:1357} INFO - Starting attempt 1 of 1
[2023-04-04 15:22:34,390] {taskinstance.py:1358} INFO - 
--------------------------------------------------------------------------------
[2023-04-04 15:22:34,411] {taskinstance.py:1377} INFO - Executing <Task(PythonOperator): extrai_dados> on 2022-09-12 00:00:00+00:00
[2023-04-04 15:22:34,413] {standard_task_runner.py:52} INFO - Started process 10282 to run task
[2023-04-04 15:22:34,415] {standard_task_runner.py:79} INFO - Running: ['airflow', 'tasks', 'run', 'dados_climaticos', 'extrai_dados', 'scheduled__2022-09-12T00:00:00+00:00', '--job-id', '37', '--raw', '--subdir', 'DAGS_FOLDER/dados_climaticos.py', '--cfg-path', '/tmp/tmppgkytlpn', '--error-file', '/tmp/tmplov_lqyb']
[2023-04-04 15:22:34,415] {standard_task_runner.py:80} INFO - Job 37: Subtask extrai_dados
[2023-04-04 15:22:34,451] {task_command.py:370} INFO - Running <TaskInstance: dados_climaticos.extrai_dados scheduled__2022-09-12T00:00:00+00:00 [running]> on host bruno-H610M-H-DDR4
[2023-04-04 15:22:34,504] {taskinstance.py:1569} INFO - Exporting the following env vars:
AIRFLOW_CTX_DAG_OWNER=airflow
AIRFLOW_CTX_DAG_ID=dados_climaticos
AIRFLOW_CTX_TASK_ID=extrai_dados
AIRFLOW_CTX_EXECUTION_DATE=2022-09-12T00:00:00+00:00
AIRFLOW_CTX_TRY_NUMBER=1
AIRFLOW_CTX_DAG_RUN_ID=scheduled__2022-09-12T00:00:00+00:00
[2023-04-04 15:22:35,285] {taskinstance.py:1889} ERROR - Task failed with exception
Traceback (most recent call last):
  File "/home/bruno/Documents/airflow_alura/venv/lib/python3.10/site-packages/airflow/operators/python.py", line 171, in execute
    return_value = self.execute_callable()
  File "/home/bruno/Documents/airflow_alura/venv/lib/python3.10/site-packages/airflow/operators/python.py", line 189, in execute_callable
    return self.python_callable(*self.op_args, **self.op_kwargs)
  File "/home/bruno/Documents/airflow_alura/dags/dados_climaticos.py", line 32, in extrai_dados
    dados[['datetime', 'tempmin', 'temp', 'tempax']].to_csv(
  File "/home/bruno/Documents/airflow_alura/venv/lib/python3.10/site-packages/pandas/core/frame.py", line 3766, in __getitem__
    indexer = self.columns._get_indexer_strict(key, "columns")[1]
  File "/home/bruno/Documents/airflow_alura/venv/lib/python3.10/site-packages/pandas/core/indexes/base.py", line 5876, in _get_indexer_strict
    self._raise_if_missing(keyarr, indexer, axis_name)
  File "/home/bruno/Documents/airflow_alura/venv/lib/python3.10/site-packages/pandas/core/indexes/base.py", line 5938, in _raise_if_missing
    raise KeyError(f"{not_found} not in index")
KeyError: "['tempax'] not in index"
[2023-04-04 15:22:35,297] {taskinstance.py:1395} INFO - Marking task as FAILED. dag_id=dados_climaticos, task_id=extrai_dados, execution_date=20220912T000000, start_date=20230404T182234, end_date=20230404T182235
[2023-04-04 15:22:35,314] {standard_task_runner.py:92} ERROR - Failed to execute job 37 for task extrai_dados ("['tempax'] not in index"; 10282)
[2023-04-04 15:22:35,349] {local_task_job.py:156} INFO - Task exited with return code 1
[2023-04-04 15:22:35,369] {local_task_job.py:273} INFO - 0 downstream tasks scheduled from follow-on schedule check
[2023-04-04 15:25:50,417] {taskinstance.py:1159} INFO - Dependencies all met for <TaskInstance: dados_climaticos.extrai_dados scheduled__2022-09-12T00:00:00+00:00 [queued]>
[2023-04-04 15:25:50,445] {taskinstance.py:1159} INFO - Dependencies all met for <TaskInstance: dados_climaticos.extrai_dados scheduled__2022-09-12T00:00:00+00:00 [queued]>
[2023-04-04 15:25:50,445] {taskinstance.py:1356} INFO - 
--------------------------------------------------------------------------------
[2023-04-04 15:25:50,445] {taskinstance.py:1357} INFO - Starting attempt 1 of 1
[2023-04-04 15:25:50,445] {taskinstance.py:1358} INFO - 
--------------------------------------------------------------------------------
[2023-04-04 15:25:50,484] {taskinstance.py:1377} INFO - Executing <Task(PythonOperator): extrai_dados> on 2022-09-12 00:00:00+00:00
[2023-04-04 15:25:50,486] {standard_task_runner.py:52} INFO - Started process 10742 to run task
[2023-04-04 15:25:50,488] {standard_task_runner.py:79} INFO - Running: ['airflow', 'tasks', 'run', 'dados_climaticos', 'extrai_dados', 'scheduled__2022-09-12T00:00:00+00:00', '--job-id', '37', '--raw', '--subdir', 'DAGS_FOLDER/dados_climaticos.py', '--cfg-path', '/tmp/tmpy4ng2rzi', '--error-file', '/tmp/tmpkq3r6zc7']
[2023-04-04 15:25:50,488] {standard_task_runner.py:80} INFO - Job 37: Subtask extrai_dados
[2023-04-04 15:25:50,525] {task_command.py:370} INFO - Running <TaskInstance: dados_climaticos.extrai_dados scheduled__2022-09-12T00:00:00+00:00 [running]> on host bruno-H610M-H-DDR4
[2023-04-04 15:25:50,569] {taskinstance.py:1569} INFO - Exporting the following env vars:
AIRFLOW_CTX_DAG_OWNER=airflow
AIRFLOW_CTX_DAG_ID=dados_climaticos
AIRFLOW_CTX_TASK_ID=extrai_dados
AIRFLOW_CTX_EXECUTION_DATE=2022-09-12T00:00:00+00:00
AIRFLOW_CTX_TRY_NUMBER=1
AIRFLOW_CTX_DAG_RUN_ID=scheduled__2022-09-12T00:00:00+00:00
[2023-04-04 15:25:51,311] {python.py:173} INFO - Done. Returned value was: None
[2023-04-04 15:25:51,315] {taskinstance.py:1395} INFO - Marking task as SUCCESS. dag_id=dados_climaticos, task_id=extrai_dados, execution_date=20220912T000000, start_date=20230404T182550, end_date=20230404T182551
[2023-04-04 15:25:51,341] {local_task_job.py:156} INFO - Task exited with return code 0
[2023-04-04 15:25:51,364] {local_task_job.py:273} INFO - 0 downstream tasks scheduled from follow-on schedule check
