[2023-04-04 14:50:07,672] {taskinstance.py:1159} INFO - Dependencies all met for <TaskInstance: dados_climaticos.extrai_dados scheduled__2022-10-03T00:00:00+00:00 [queued]>
[2023-04-04 14:50:07,675] {taskinstance.py:1159} INFO - Dependencies all met for <TaskInstance: dados_climaticos.extrai_dados scheduled__2022-10-03T00:00:00+00:00 [queued]>
[2023-04-04 14:50:07,675] {taskinstance.py:1356} INFO - 
--------------------------------------------------------------------------------
[2023-04-04 14:50:07,675] {taskinstance.py:1357} INFO - Starting attempt 1 of 1
[2023-04-04 14:50:07,675] {taskinstance.py:1358} INFO - 
--------------------------------------------------------------------------------
[2023-04-04 14:50:07,697] {taskinstance.py:1377} INFO - Executing <Task(PythonOperator): extrai_dados> on 2022-10-03 00:00:00+00:00
[2023-04-04 14:50:07,700] {standard_task_runner.py:52} INFO - Started process 14835 to run task
[2023-04-04 14:50:07,703] {standard_task_runner.py:79} INFO - Running: ['airflow', 'tasks', 'run', 'dados_climaticos', 'extrai_dados', 'scheduled__2022-10-03T00:00:00+00:00', '--job-id', '41', '--raw', '--subdir', 'DAGS_FOLDER/dados_climaticos.py', '--cfg-path', '/tmp/tmpjia9cf6e', '--error-file', '/tmp/tmp_0642mii']
[2023-04-04 14:50:07,704] {standard_task_runner.py:80} INFO - Job 41: Subtask extrai_dados
[2023-04-04 14:50:07,750] {task_command.py:370} INFO - Running <TaskInstance: dados_climaticos.extrai_dados scheduled__2022-10-03T00:00:00+00:00 [running]> on host bruno-H610M-H-DDR4
[2023-04-04 14:50:07,795] {taskinstance.py:1569} INFO - Exporting the following env vars:
AIRFLOW_CTX_DAG_OWNER=airflow
AIRFLOW_CTX_DAG_ID=dados_climaticos
AIRFLOW_CTX_TASK_ID=extrai_dados
AIRFLOW_CTX_EXECUTION_DATE=2022-10-03T00:00:00+00:00
AIRFLOW_CTX_TRY_NUMBER=1
AIRFLOW_CTX_DAG_RUN_ID=scheduled__2022-10-03T00:00:00+00:00
[2023-04-04 14:50:08,462] {taskinstance.py:1889} ERROR - Task failed with exception
Traceback (most recent call last):
  File "/home/bruno/Documents/airflow_alura/venv/lib/python3.10/site-packages/airflow/operators/python.py", line 171, in execute
    return_value = self.execute_callable()
  File "/home/bruno/Documents/airflow_alura/venv/lib/python3.10/site-packages/airflow/operators/python.py", line 189, in execute_callable
    return self.python_callable(*self.op_args, **self.op_kwargs)
  File "/home/bruno/Documents/airflow_alura/dags/dados_climaticos.py", line 27, in extrai_dados
    dados = pd.read_csv(URL)
  File "/home/bruno/Documents/airflow_alura/venv/lib/python3.10/site-packages/pandas/io/parsers/readers.py", line 912, in read_csv
    return _read(filepath_or_buffer, kwds)
  File "/home/bruno/Documents/airflow_alura/venv/lib/python3.10/site-packages/pandas/io/parsers/readers.py", line 577, in _read
    parser = TextFileReader(filepath_or_buffer, **kwds)
  File "/home/bruno/Documents/airflow_alura/venv/lib/python3.10/site-packages/pandas/io/parsers/readers.py", line 1407, in __init__
    self._engine = self._make_engine(f, self.engine)
  File "/home/bruno/Documents/airflow_alura/venv/lib/python3.10/site-packages/pandas/io/parsers/readers.py", line 1661, in _make_engine
    self.handles = get_handle(
  File "/home/bruno/Documents/airflow_alura/venv/lib/python3.10/site-packages/pandas/io/common.py", line 716, in get_handle
    ioargs = _get_filepath_or_buffer(
  File "/home/bruno/Documents/airflow_alura/venv/lib/python3.10/site-packages/pandas/io/common.py", line 368, in _get_filepath_or_buffer
    with urlopen(req_info) as req:
  File "/home/bruno/Documents/airflow_alura/venv/lib/python3.10/site-packages/pandas/io/common.py", line 270, in urlopen
    return urllib.request.urlopen(*args, **kwargs)
  File "/usr/lib/python3.10/urllib/request.py", line 216, in urlopen
    return opener.open(url, data, timeout)
  File "/usr/lib/python3.10/urllib/request.py", line 525, in open
    response = meth(req, response)
  File "/usr/lib/python3.10/urllib/request.py", line 634, in http_response
    response = self.parent.error(
  File "/usr/lib/python3.10/urllib/request.py", line 563, in error
    return self._call_chain(*args)
  File "/usr/lib/python3.10/urllib/request.py", line 496, in _call_chain
    result = func(*args)
  File "/usr/lib/python3.10/urllib/request.py", line 643, in http_error_default
    raise HTTPError(req.full_url, code, msg, hdrs, fp)
urllib.error.HTTPError: HTTP Error 401: 
[2023-04-04 14:50:08,473] {taskinstance.py:1395} INFO - Marking task as FAILED. dag_id=dados_climaticos, task_id=extrai_dados, execution_date=20221003T000000, start_date=20230404T175007, end_date=20230404T175008
[2023-04-04 14:50:08,505] {standard_task_runner.py:92} ERROR - Failed to execute job 41 for task extrai_dados (HTTP Error 401: ; 14835)
[2023-04-04 14:50:08,556] {local_task_job.py:156} INFO - Task exited with return code 1
[2023-04-04 14:50:08,575] {local_task_job.py:273} INFO - 0 downstream tasks scheduled from follow-on schedule check
[2023-04-04 15:15:14,544] {taskinstance.py:1159} INFO - Dependencies all met for <TaskInstance: dados_climaticos.extrai_dados scheduled__2022-10-03T00:00:00+00:00 [queued]>
[2023-04-04 15:15:14,558] {taskinstance.py:1159} INFO - Dependencies all met for <TaskInstance: dados_climaticos.extrai_dados scheduled__2022-10-03T00:00:00+00:00 [queued]>
[2023-04-04 15:15:14,558] {taskinstance.py:1356} INFO - 
--------------------------------------------------------------------------------
[2023-04-04 15:15:14,558] {taskinstance.py:1357} INFO - Starting attempt 1 of 1
[2023-04-04 15:15:14,558] {taskinstance.py:1358} INFO - 
--------------------------------------------------------------------------------
[2023-04-04 15:15:14,579] {taskinstance.py:1377} INFO - Executing <Task(PythonOperator): extrai_dados> on 2022-10-03 00:00:00+00:00
[2023-04-04 15:15:14,582] {standard_task_runner.py:52} INFO - Started process 8710 to run task
[2023-04-04 15:15:14,584] {standard_task_runner.py:79} INFO - Running: ['airflow', 'tasks', 'run', 'dados_climaticos', 'extrai_dados', 'scheduled__2022-10-03T00:00:00+00:00', '--job-id', '38', '--raw', '--subdir', 'DAGS_FOLDER/dados_climaticos.py', '--cfg-path', '/tmp/tmpnh4bolz7', '--error-file', '/tmp/tmp9a4iny9c']
[2023-04-04 15:15:14,585] {standard_task_runner.py:80} INFO - Job 38: Subtask extrai_dados
[2023-04-04 15:15:14,627] {task_command.py:370} INFO - Running <TaskInstance: dados_climaticos.extrai_dados scheduled__2022-10-03T00:00:00+00:00 [running]> on host bruno-H610M-H-DDR4
[2023-04-04 15:15:14,675] {taskinstance.py:1569} INFO - Exporting the following env vars:
AIRFLOW_CTX_DAG_OWNER=airflow
AIRFLOW_CTX_DAG_ID=dados_climaticos
AIRFLOW_CTX_TASK_ID=extrai_dados
AIRFLOW_CTX_EXECUTION_DATE=2022-10-03T00:00:00+00:00
AIRFLOW_CTX_TRY_NUMBER=1
AIRFLOW_CTX_DAG_RUN_ID=scheduled__2022-10-03T00:00:00+00:00
[2023-04-04 15:15:15,385] {taskinstance.py:1889} ERROR - Task failed with exception
Traceback (most recent call last):
  File "/home/bruno/Documents/airflow_alura/venv/lib/python3.10/site-packages/airflow/operators/python.py", line 171, in execute
    return_value = self.execute_callable()
  File "/home/bruno/Documents/airflow_alura/venv/lib/python3.10/site-packages/airflow/operators/python.py", line 189, in execute_callable
    return self.python_callable(*self.op_args, **self.op_kwargs)
  File "/home/bruno/Documents/airflow_alura/dags/dados_climaticos.py", line 27, in extrai_dados
    dados = pd.read_csv(URL)
  File "/home/bruno/Documents/airflow_alura/venv/lib/python3.10/site-packages/pandas/io/parsers/readers.py", line 912, in read_csv
    return _read(filepath_or_buffer, kwds)
  File "/home/bruno/Documents/airflow_alura/venv/lib/python3.10/site-packages/pandas/io/parsers/readers.py", line 577, in _read
    parser = TextFileReader(filepath_or_buffer, **kwds)
  File "/home/bruno/Documents/airflow_alura/venv/lib/python3.10/site-packages/pandas/io/parsers/readers.py", line 1407, in __init__
    self._engine = self._make_engine(f, self.engine)
  File "/home/bruno/Documents/airflow_alura/venv/lib/python3.10/site-packages/pandas/io/parsers/readers.py", line 1661, in _make_engine
    self.handles = get_handle(
  File "/home/bruno/Documents/airflow_alura/venv/lib/python3.10/site-packages/pandas/io/common.py", line 716, in get_handle
    ioargs = _get_filepath_or_buffer(
  File "/home/bruno/Documents/airflow_alura/venv/lib/python3.10/site-packages/pandas/io/common.py", line 368, in _get_filepath_or_buffer
    with urlopen(req_info) as req:
  File "/home/bruno/Documents/airflow_alura/venv/lib/python3.10/site-packages/pandas/io/common.py", line 270, in urlopen
    return urllib.request.urlopen(*args, **kwargs)
  File "/usr/lib/python3.10/urllib/request.py", line 216, in urlopen
    return opener.open(url, data, timeout)
  File "/usr/lib/python3.10/urllib/request.py", line 525, in open
    response = meth(req, response)
  File "/usr/lib/python3.10/urllib/request.py", line 634, in http_response
    response = self.parent.error(
  File "/usr/lib/python3.10/urllib/request.py", line 563, in error
    return self._call_chain(*args)
  File "/usr/lib/python3.10/urllib/request.py", line 496, in _call_chain
    result = func(*args)
  File "/usr/lib/python3.10/urllib/request.py", line 643, in http_error_default
    raise HTTPError(req.full_url, code, msg, hdrs, fp)
urllib.error.HTTPError: HTTP Error 401: 
[2023-04-04 15:15:15,390] {taskinstance.py:1395} INFO - Marking task as FAILED. dag_id=dados_climaticos, task_id=extrai_dados, execution_date=20221003T000000, start_date=20230404T181514, end_date=20230404T181515
[2023-04-04 15:15:15,406] {standard_task_runner.py:92} ERROR - Failed to execute job 38 for task extrai_dados (HTTP Error 401: ; 8710)
[2023-04-04 15:15:15,438] {local_task_job.py:156} INFO - Task exited with return code 1
[2023-04-04 15:15:15,460] {local_task_job.py:273} INFO - 0 downstream tasks scheduled from follow-on schedule check
[2023-04-04 15:18:46,142] {taskinstance.py:1159} INFO - Dependencies all met for <TaskInstance: dados_climaticos.extrai_dados scheduled__2022-10-03T00:00:00+00:00 [queued]>
[2023-04-04 15:18:46,155] {taskinstance.py:1159} INFO - Dependencies all met for <TaskInstance: dados_climaticos.extrai_dados scheduled__2022-10-03T00:00:00+00:00 [queued]>
[2023-04-04 15:18:46,155] {taskinstance.py:1356} INFO - 
--------------------------------------------------------------------------------
[2023-04-04 15:18:46,156] {taskinstance.py:1357} INFO - Starting attempt 1 of 1
[2023-04-04 15:18:46,156] {taskinstance.py:1358} INFO - 
--------------------------------------------------------------------------------
[2023-04-04 15:18:46,178] {taskinstance.py:1377} INFO - Executing <Task(PythonOperator): extrai_dados> on 2022-10-03 00:00:00+00:00
[2023-04-04 15:18:46,181] {standard_task_runner.py:52} INFO - Started process 9676 to run task
[2023-04-04 15:18:46,185] {standard_task_runner.py:79} INFO - Running: ['airflow', 'tasks', 'run', 'dados_climaticos', 'extrai_dados', 'scheduled__2022-10-03T00:00:00+00:00', '--job-id', '43', '--raw', '--subdir', 'DAGS_FOLDER/dados_climaticos.py', '--cfg-path', '/tmp/tmpm75x6fco', '--error-file', '/tmp/tmp25g7ck15']
[2023-04-04 15:18:46,186] {standard_task_runner.py:80} INFO - Job 43: Subtask extrai_dados
[2023-04-04 15:18:46,228] {task_command.py:370} INFO - Running <TaskInstance: dados_climaticos.extrai_dados scheduled__2022-10-03T00:00:00+00:00 [running]> on host bruno-H610M-H-DDR4
[2023-04-04 15:18:46,297] {taskinstance.py:1569} INFO - Exporting the following env vars:
AIRFLOW_CTX_DAG_OWNER=airflow
AIRFLOW_CTX_DAG_ID=dados_climaticos
AIRFLOW_CTX_TASK_ID=extrai_dados
AIRFLOW_CTX_EXECUTION_DATE=2022-10-03T00:00:00+00:00
AIRFLOW_CTX_TRY_NUMBER=1
AIRFLOW_CTX_DAG_RUN_ID=scheduled__2022-10-03T00:00:00+00:00
[2023-04-04 15:18:47,152] {taskinstance.py:1889} ERROR - Task failed with exception
Traceback (most recent call last):
  File "/home/bruno/Documents/airflow_alura/venv/lib/python3.10/site-packages/airflow/operators/python.py", line 171, in execute
    return_value = self.execute_callable()
  File "/home/bruno/Documents/airflow_alura/venv/lib/python3.10/site-packages/airflow/operators/python.py", line 189, in execute_callable
    return self.python_callable(*self.op_args, **self.op_kwargs)
  File "/home/bruno/Documents/airflow_alura/dags/dados_climaticos.py", line 32, in extrai_dados
    dados[['datetime', 'tempmin', 'temp', 'tempax']].to_csv(
  File "/home/bruno/Documents/airflow_alura/venv/lib/python3.10/site-packages/pandas/core/frame.py", line 3766, in __getitem__
    indexer = self.columns._get_indexer_strict(key, "columns")[1]
  File "/home/bruno/Documents/airflow_alura/venv/lib/python3.10/site-packages/pandas/core/indexes/base.py", line 5876, in _get_indexer_strict
    self._raise_if_missing(keyarr, indexer, axis_name)
  File "/home/bruno/Documents/airflow_alura/venv/lib/python3.10/site-packages/pandas/core/indexes/base.py", line 5938, in _raise_if_missing
    raise KeyError(f"{not_found} not in index")
KeyError: "['tempax'] not in index"
[2023-04-04 15:18:47,159] {taskinstance.py:1395} INFO - Marking task as FAILED. dag_id=dados_climaticos, task_id=extrai_dados, execution_date=20221003T000000, start_date=20230404T181846, end_date=20230404T181847
[2023-04-04 15:18:47,178] {standard_task_runner.py:92} ERROR - Failed to execute job 43 for task extrai_dados ("['tempax'] not in index"; 9676)
[2023-04-04 15:18:47,198] {local_task_job.py:156} INFO - Task exited with return code 1
[2023-04-04 15:18:47,213] {local_task_job.py:273} INFO - 0 downstream tasks scheduled from follow-on schedule check
[2023-04-04 15:26:02,162] {taskinstance.py:1159} INFO - Dependencies all met for <TaskInstance: dados_climaticos.extrai_dados scheduled__2022-10-03T00:00:00+00:00 [queued]>
[2023-04-04 15:26:02,175] {taskinstance.py:1159} INFO - Dependencies all met for <TaskInstance: dados_climaticos.extrai_dados scheduled__2022-10-03T00:00:00+00:00 [queued]>
[2023-04-04 15:26:02,175] {taskinstance.py:1356} INFO - 
--------------------------------------------------------------------------------
[2023-04-04 15:26:02,175] {taskinstance.py:1357} INFO - Starting attempt 1 of 1
[2023-04-04 15:26:02,175] {taskinstance.py:1358} INFO - 
--------------------------------------------------------------------------------
[2023-04-04 15:26:02,197] {taskinstance.py:1377} INFO - Executing <Task(PythonOperator): extrai_dados> on 2022-10-03 00:00:00+00:00
[2023-04-04 15:26:02,199] {standard_task_runner.py:52} INFO - Started process 10819 to run task
[2023-04-04 15:26:02,201] {standard_task_runner.py:79} INFO - Running: ['airflow', 'tasks', 'run', 'dados_climaticos', 'extrai_dados', 'scheduled__2022-10-03T00:00:00+00:00', '--job-id', '43', '--raw', '--subdir', 'DAGS_FOLDER/dados_climaticos.py', '--cfg-path', '/tmp/tmpdldh5kni', '--error-file', '/tmp/tmpy0ei2zoa']
[2023-04-04 15:26:02,202] {standard_task_runner.py:80} INFO - Job 43: Subtask extrai_dados
[2023-04-04 15:26:02,243] {task_command.py:370} INFO - Running <TaskInstance: dados_climaticos.extrai_dados scheduled__2022-10-03T00:00:00+00:00 [running]> on host bruno-H610M-H-DDR4
[2023-04-04 15:26:02,296] {taskinstance.py:1569} INFO - Exporting the following env vars:
AIRFLOW_CTX_DAG_OWNER=airflow
AIRFLOW_CTX_DAG_ID=dados_climaticos
AIRFLOW_CTX_TASK_ID=extrai_dados
AIRFLOW_CTX_EXECUTION_DATE=2022-10-03T00:00:00+00:00
AIRFLOW_CTX_TRY_NUMBER=1
AIRFLOW_CTX_DAG_RUN_ID=scheduled__2022-10-03T00:00:00+00:00
[2023-04-04 15:26:03,053] {python.py:173} INFO - Done. Returned value was: None
[2023-04-04 15:26:03,058] {taskinstance.py:1395} INFO - Marking task as SUCCESS. dag_id=dados_climaticos, task_id=extrai_dados, execution_date=20221003T000000, start_date=20230404T182602, end_date=20230404T182603
[2023-04-04 15:26:03,095] {local_task_job.py:156} INFO - Task exited with return code 0
[2023-04-04 15:26:03,118] {local_task_job.py:273} INFO - 0 downstream tasks scheduled from follow-on schedule check
