[2023-04-04 14:49:45,742] {taskinstance.py:1159} INFO - Dependencies all met for <TaskInstance: dados_climaticos.extrai_dados scheduled__2022-08-22T00:00:00+00:00 [queued]>
[2023-04-04 14:49:45,745] {taskinstance.py:1159} INFO - Dependencies all met for <TaskInstance: dados_climaticos.extrai_dados scheduled__2022-08-22T00:00:00+00:00 [queued]>
[2023-04-04 14:49:45,745] {taskinstance.py:1356} INFO - 
--------------------------------------------------------------------------------
[2023-04-04 14:49:45,745] {taskinstance.py:1357} INFO - Starting attempt 1 of 1
[2023-04-04 14:49:45,745] {taskinstance.py:1358} INFO - 
--------------------------------------------------------------------------------
[2023-04-04 14:49:45,767] {taskinstance.py:1377} INFO - Executing <Task(PythonOperator): extrai_dados> on 2022-08-22 00:00:00+00:00
[2023-04-04 14:49:45,769] {standard_task_runner.py:52} INFO - Started process 14684 to run task
[2023-04-04 14:49:45,772] {standard_task_runner.py:79} INFO - Running: ['airflow', 'tasks', 'run', 'dados_climaticos', 'extrai_dados', 'scheduled__2022-08-22T00:00:00+00:00', '--job-id', '29', '--raw', '--subdir', 'DAGS_FOLDER/dados_climaticos.py', '--cfg-path', '/tmp/tmpn4jeobsr', '--error-file', '/tmp/tmpfnqqsarh']
[2023-04-04 14:49:45,774] {standard_task_runner.py:80} INFO - Job 29: Subtask extrai_dados
[2023-04-04 14:49:45,807] {task_command.py:370} INFO - Running <TaskInstance: dados_climaticos.extrai_dados scheduled__2022-08-22T00:00:00+00:00 [running]> on host bruno-H610M-H-DDR4
[2023-04-04 14:49:45,855] {taskinstance.py:1569} INFO - Exporting the following env vars:
AIRFLOW_CTX_DAG_OWNER=airflow
AIRFLOW_CTX_DAG_ID=dados_climaticos
AIRFLOW_CTX_TASK_ID=extrai_dados
AIRFLOW_CTX_EXECUTION_DATE=2022-08-22T00:00:00+00:00
AIRFLOW_CTX_TRY_NUMBER=1
AIRFLOW_CTX_DAG_RUN_ID=scheduled__2022-08-22T00:00:00+00:00
[2023-04-04 14:49:46,636] {taskinstance.py:1889} ERROR - Task failed with exception
Traceback (most recent call last):
  File "/home/bruno/Documents/airflow_alura/venv/lib/python3.10/site-packages/airflow/operators/python.py", line 171, in execute
    return_value = self.execute_callable()
  File "/home/bruno/Documents/airflow_alura/venv/lib/python3.10/site-packages/airflow/operators/python.py", line 189, in execute_callable
    return self.python_callable(*self.op_args, **self.op_kwargs)
  File "/home/bruno/Documents/airflow_alura/dags/dados_climaticos.py", line 27, in extrai_dados
    dados = pd.read_csv(URL)
  File "/home/bruno/Documents/airflow_alura/venv/lib/python3.10/site-packages/pandas/io/parsers/readers.py", line 912, in read_csv
    return _read(filepath_or_buffer, kwds)
  File "/home/bruno/Documents/airflow_alura/venv/lib/python3.10/site-packages/pandas/io/parsers/readers.py", line 577, in _read
    parser = TextFileReader(filepath_or_buffer, **kwds)
  File "/home/bruno/Documents/airflow_alura/venv/lib/python3.10/site-packages/pandas/io/parsers/readers.py", line 1407, in __init__
    self._engine = self._make_engine(f, self.engine)
  File "/home/bruno/Documents/airflow_alura/venv/lib/python3.10/site-packages/pandas/io/parsers/readers.py", line 1661, in _make_engine
    self.handles = get_handle(
  File "/home/bruno/Documents/airflow_alura/venv/lib/python3.10/site-packages/pandas/io/common.py", line 716, in get_handle
    ioargs = _get_filepath_or_buffer(
  File "/home/bruno/Documents/airflow_alura/venv/lib/python3.10/site-packages/pandas/io/common.py", line 368, in _get_filepath_or_buffer
    with urlopen(req_info) as req:
  File "/home/bruno/Documents/airflow_alura/venv/lib/python3.10/site-packages/pandas/io/common.py", line 270, in urlopen
    return urllib.request.urlopen(*args, **kwargs)
  File "/usr/lib/python3.10/urllib/request.py", line 216, in urlopen
    return opener.open(url, data, timeout)
  File "/usr/lib/python3.10/urllib/request.py", line 525, in open
    response = meth(req, response)
  File "/usr/lib/python3.10/urllib/request.py", line 634, in http_response
    response = self.parent.error(
  File "/usr/lib/python3.10/urllib/request.py", line 563, in error
    return self._call_chain(*args)
  File "/usr/lib/python3.10/urllib/request.py", line 496, in _call_chain
    result = func(*args)
  File "/usr/lib/python3.10/urllib/request.py", line 643, in http_error_default
    raise HTTPError(req.full_url, code, msg, hdrs, fp)
urllib.error.HTTPError: HTTP Error 401: 
[2023-04-04 14:49:46,660] {taskinstance.py:1395} INFO - Marking task as FAILED. dag_id=dados_climaticos, task_id=extrai_dados, execution_date=20220822T000000, start_date=20230404T174945, end_date=20230404T174946
[2023-04-04 14:49:46,687] {standard_task_runner.py:92} ERROR - Failed to execute job 29 for task extrai_dados (HTTP Error 401: ; 14684)
[2023-04-04 14:49:46,706] {local_task_job.py:156} INFO - Task exited with return code 1
[2023-04-04 14:49:46,728] {local_task_job.py:273} INFO - 0 downstream tasks scheduled from follow-on schedule check
[2023-04-04 15:18:23,498] {taskinstance.py:1159} INFO - Dependencies all met for <TaskInstance: dados_climaticos.extrai_dados scheduled__2022-08-22T00:00:00+00:00 [queued]>
[2023-04-04 15:18:23,512] {taskinstance.py:1159} INFO - Dependencies all met for <TaskInstance: dados_climaticos.extrai_dados scheduled__2022-08-22T00:00:00+00:00 [queued]>
[2023-04-04 15:18:23,512] {taskinstance.py:1356} INFO - 
--------------------------------------------------------------------------------
[2023-04-04 15:18:23,512] {taskinstance.py:1357} INFO - Starting attempt 1 of 1
[2023-04-04 15:18:23,512] {taskinstance.py:1358} INFO - 
--------------------------------------------------------------------------------
[2023-04-04 15:18:23,533] {taskinstance.py:1377} INFO - Executing <Task(PythonOperator): extrai_dados> on 2022-08-22 00:00:00+00:00
[2023-04-04 15:18:23,536] {standard_task_runner.py:52} INFO - Started process 9534 to run task
[2023-04-04 15:18:23,538] {standard_task_runner.py:79} INFO - Running: ['airflow', 'tasks', 'run', 'dados_climaticos', 'extrai_dados', 'scheduled__2022-08-22T00:00:00+00:00', '--job-id', '31', '--raw', '--subdir', 'DAGS_FOLDER/dados_climaticos.py', '--cfg-path', '/tmp/tmp7na2d31y', '--error-file', '/tmp/tmp0ojg6t9b']
[2023-04-04 15:18:23,539] {standard_task_runner.py:80} INFO - Job 31: Subtask extrai_dados
[2023-04-04 15:18:23,579] {task_command.py:370} INFO - Running <TaskInstance: dados_climaticos.extrai_dados scheduled__2022-08-22T00:00:00+00:00 [running]> on host bruno-H610M-H-DDR4
[2023-04-04 15:18:23,632] {taskinstance.py:1569} INFO - Exporting the following env vars:
AIRFLOW_CTX_DAG_OWNER=airflow
AIRFLOW_CTX_DAG_ID=dados_climaticos
AIRFLOW_CTX_TASK_ID=extrai_dados
AIRFLOW_CTX_EXECUTION_DATE=2022-08-22T00:00:00+00:00
AIRFLOW_CTX_TRY_NUMBER=1
AIRFLOW_CTX_DAG_RUN_ID=scheduled__2022-08-22T00:00:00+00:00
[2023-04-04 15:18:24,601] {taskinstance.py:1889} ERROR - Task failed with exception
Traceback (most recent call last):
  File "/home/bruno/Documents/airflow_alura/venv/lib/python3.10/site-packages/airflow/operators/python.py", line 171, in execute
    return_value = self.execute_callable()
  File "/home/bruno/Documents/airflow_alura/venv/lib/python3.10/site-packages/airflow/operators/python.py", line 189, in execute_callable
    return self.python_callable(*self.op_args, **self.op_kwargs)
  File "/home/bruno/Documents/airflow_alura/dags/dados_climaticos.py", line 32, in extrai_dados
    dados[['datetime', 'tempmin', 'temp', 'tempax']].to_csv(
  File "/home/bruno/Documents/airflow_alura/venv/lib/python3.10/site-packages/pandas/core/frame.py", line 3766, in __getitem__
    indexer = self.columns._get_indexer_strict(key, "columns")[1]
  File "/home/bruno/Documents/airflow_alura/venv/lib/python3.10/site-packages/pandas/core/indexes/base.py", line 5876, in _get_indexer_strict
    self._raise_if_missing(keyarr, indexer, axis_name)
  File "/home/bruno/Documents/airflow_alura/venv/lib/python3.10/site-packages/pandas/core/indexes/base.py", line 5938, in _raise_if_missing
    raise KeyError(f"{not_found} not in index")
KeyError: "['tempax'] not in index"
[2023-04-04 15:18:24,625] {taskinstance.py:1395} INFO - Marking task as FAILED. dag_id=dados_climaticos, task_id=extrai_dados, execution_date=20220822T000000, start_date=20230404T181823, end_date=20230404T181824
[2023-04-04 15:18:24,651] {standard_task_runner.py:92} ERROR - Failed to execute job 31 for task extrai_dados ("['tempax'] not in index"; 9534)
[2023-04-04 15:18:24,673] {local_task_job.py:156} INFO - Task exited with return code 1
[2023-04-04 15:18:24,691] {local_task_job.py:273} INFO - 0 downstream tasks scheduled from follow-on schedule check
[2023-04-04 15:20:39,281] {taskinstance.py:1159} INFO - Dependencies all met for <TaskInstance: dados_climaticos.extrai_dados scheduled__2022-08-22T00:00:00+00:00 [queued]>
[2023-04-04 15:20:39,295] {taskinstance.py:1159} INFO - Dependencies all met for <TaskInstance: dados_climaticos.extrai_dados scheduled__2022-08-22T00:00:00+00:00 [queued]>
[2023-04-04 15:20:39,295] {taskinstance.py:1356} INFO - 
--------------------------------------------------------------------------------
[2023-04-04 15:20:39,295] {taskinstance.py:1357} INFO - Starting attempt 1 of 1
[2023-04-04 15:20:39,295] {taskinstance.py:1358} INFO - 
--------------------------------------------------------------------------------
[2023-04-04 15:20:39,316] {taskinstance.py:1377} INFO - Executing <Task(PythonOperator): extrai_dados> on 2022-08-22 00:00:00+00:00
[2023-04-04 15:20:39,318] {standard_task_runner.py:52} INFO - Started process 9929 to run task
[2023-04-04 15:20:39,321] {standard_task_runner.py:79} INFO - Running: ['airflow', 'tasks', 'run', 'dados_climaticos', 'extrai_dados', 'scheduled__2022-08-22T00:00:00+00:00', '--job-id', '31', '--raw', '--subdir', 'DAGS_FOLDER/dados_climaticos.py', '--cfg-path', '/tmp/tmpem5gts9y', '--error-file', '/tmp/tmp0zos7tea']
[2023-04-04 15:20:39,321] {standard_task_runner.py:80} INFO - Job 31: Subtask extrai_dados
[2023-04-04 15:20:39,364] {task_command.py:370} INFO - Running <TaskInstance: dados_climaticos.extrai_dados scheduled__2022-08-22T00:00:00+00:00 [running]> on host bruno-H610M-H-DDR4
[2023-04-04 15:20:39,424] {taskinstance.py:1569} INFO - Exporting the following env vars:
AIRFLOW_CTX_DAG_OWNER=airflow
AIRFLOW_CTX_DAG_ID=dados_climaticos
AIRFLOW_CTX_TASK_ID=extrai_dados
AIRFLOW_CTX_EXECUTION_DATE=2022-08-22T00:00:00+00:00
AIRFLOW_CTX_TRY_NUMBER=1
AIRFLOW_CTX_DAG_RUN_ID=scheduled__2022-08-22T00:00:00+00:00
[2023-04-04 15:20:40,336] {taskinstance.py:1889} ERROR - Task failed with exception
Traceback (most recent call last):
  File "/home/bruno/Documents/airflow_alura/venv/lib/python3.10/site-packages/airflow/operators/python.py", line 171, in execute
    return_value = self.execute_callable()
  File "/home/bruno/Documents/airflow_alura/venv/lib/python3.10/site-packages/airflow/operators/python.py", line 189, in execute_callable
    return self.python_callable(*self.op_args, **self.op_kwargs)
  File "/home/bruno/Documents/airflow_alura/dags/dados_climaticos.py", line 32, in extrai_dados
    dados[['datetime', 'tempmin', 'temp', 'tempax']].to_csv(
  File "/home/bruno/Documents/airflow_alura/venv/lib/python3.10/site-packages/pandas/core/frame.py", line 3766, in __getitem__
    indexer = self.columns._get_indexer_strict(key, "columns")[1]
  File "/home/bruno/Documents/airflow_alura/venv/lib/python3.10/site-packages/pandas/core/indexes/base.py", line 5876, in _get_indexer_strict
    self._raise_if_missing(keyarr, indexer, axis_name)
  File "/home/bruno/Documents/airflow_alura/venv/lib/python3.10/site-packages/pandas/core/indexes/base.py", line 5938, in _raise_if_missing
    raise KeyError(f"{not_found} not in index")
KeyError: "['tempax'] not in index"
[2023-04-04 15:20:40,340] {taskinstance.py:1395} INFO - Marking task as FAILED. dag_id=dados_climaticos, task_id=extrai_dados, execution_date=20220822T000000, start_date=20230404T182039, end_date=20230404T182040
[2023-04-04 15:20:40,362] {standard_task_runner.py:92} ERROR - Failed to execute job 31 for task extrai_dados ("['tempax'] not in index"; 9929)
[2023-04-04 15:20:40,375] {local_task_job.py:156} INFO - Task exited with return code 1
[2023-04-04 15:20:40,397] {local_task_job.py:273} INFO - 0 downstream tasks scheduled from follow-on schedule check
[2023-04-04 15:22:23,045] {taskinstance.py:1159} INFO - Dependencies all met for <TaskInstance: dados_climaticos.extrai_dados scheduled__2022-08-22T00:00:00+00:00 [queued]>
[2023-04-04 15:22:23,082] {taskinstance.py:1159} INFO - Dependencies all met for <TaskInstance: dados_climaticos.extrai_dados scheduled__2022-08-22T00:00:00+00:00 [queued]>
[2023-04-04 15:22:23,082] {taskinstance.py:1356} INFO - 
--------------------------------------------------------------------------------
[2023-04-04 15:22:23,082] {taskinstance.py:1357} INFO - Starting attempt 1 of 1
[2023-04-04 15:22:23,082] {taskinstance.py:1358} INFO - 
--------------------------------------------------------------------------------
[2023-04-04 15:22:23,131] {taskinstance.py:1377} INFO - Executing <Task(PythonOperator): extrai_dados> on 2022-08-22 00:00:00+00:00
[2023-04-04 15:22:23,137] {standard_task_runner.py:52} INFO - Started process 10210 to run task
[2023-04-04 15:22:23,143] {standard_task_runner.py:79} INFO - Running: ['airflow', 'tasks', 'run', 'dados_climaticos', 'extrai_dados', 'scheduled__2022-08-22T00:00:00+00:00', '--job-id', '31', '--raw', '--subdir', 'DAGS_FOLDER/dados_climaticos.py', '--cfg-path', '/tmp/tmpen27i8yo', '--error-file', '/tmp/tmpk8kc47yh']
[2023-04-04 15:22:23,144] {standard_task_runner.py:80} INFO - Job 31: Subtask extrai_dados
[2023-04-04 15:22:23,243] {task_command.py:370} INFO - Running <TaskInstance: dados_climaticos.extrai_dados scheduled__2022-08-22T00:00:00+00:00 [running]> on host bruno-H610M-H-DDR4
[2023-04-04 15:22:23,315] {taskinstance.py:1569} INFO - Exporting the following env vars:
AIRFLOW_CTX_DAG_OWNER=airflow
AIRFLOW_CTX_DAG_ID=dados_climaticos
AIRFLOW_CTX_TASK_ID=extrai_dados
AIRFLOW_CTX_EXECUTION_DATE=2022-08-22T00:00:00+00:00
AIRFLOW_CTX_TRY_NUMBER=1
AIRFLOW_CTX_DAG_RUN_ID=scheduled__2022-08-22T00:00:00+00:00
[2023-04-04 15:22:24,110] {taskinstance.py:1889} ERROR - Task failed with exception
Traceback (most recent call last):
  File "/home/bruno/Documents/airflow_alura/venv/lib/python3.10/site-packages/airflow/operators/python.py", line 171, in execute
    return_value = self.execute_callable()
  File "/home/bruno/Documents/airflow_alura/venv/lib/python3.10/site-packages/airflow/operators/python.py", line 189, in execute_callable
    return self.python_callable(*self.op_args, **self.op_kwargs)
  File "/home/bruno/Documents/airflow_alura/dags/dados_climaticos.py", line 32, in extrai_dados
    dados[['datetime', 'tempmin', 'temp', 'tempax']].to_csv(
  File "/home/bruno/Documents/airflow_alura/venv/lib/python3.10/site-packages/pandas/core/frame.py", line 3766, in __getitem__
    indexer = self.columns._get_indexer_strict(key, "columns")[1]
  File "/home/bruno/Documents/airflow_alura/venv/lib/python3.10/site-packages/pandas/core/indexes/base.py", line 5876, in _get_indexer_strict
    self._raise_if_missing(keyarr, indexer, axis_name)
  File "/home/bruno/Documents/airflow_alura/venv/lib/python3.10/site-packages/pandas/core/indexes/base.py", line 5938, in _raise_if_missing
    raise KeyError(f"{not_found} not in index")
KeyError: "['tempax'] not in index"
[2023-04-04 15:22:24,221] {taskinstance.py:1395} INFO - Marking task as FAILED. dag_id=dados_climaticos, task_id=extrai_dados, execution_date=20220822T000000, start_date=20230404T182223, end_date=20230404T182224
[2023-04-04 15:22:24,260] {standard_task_runner.py:92} ERROR - Failed to execute job 31 for task extrai_dados ("['tempax'] not in index"; 10210)
[2023-04-04 15:22:24,278] {local_task_job.py:156} INFO - Task exited with return code 1
[2023-04-04 15:22:24,286] {local_task_job.py:273} INFO - 0 downstream tasks scheduled from follow-on schedule check
[2023-04-04 15:25:39,258] {taskinstance.py:1159} INFO - Dependencies all met for <TaskInstance: dados_climaticos.extrai_dados scheduled__2022-08-22T00:00:00+00:00 [queued]>
[2023-04-04 15:25:39,272] {taskinstance.py:1159} INFO - Dependencies all met for <TaskInstance: dados_climaticos.extrai_dados scheduled__2022-08-22T00:00:00+00:00 [queued]>
[2023-04-04 15:25:39,272] {taskinstance.py:1356} INFO - 
--------------------------------------------------------------------------------
[2023-04-04 15:25:39,272] {taskinstance.py:1357} INFO - Starting attempt 1 of 1
[2023-04-04 15:25:39,272] {taskinstance.py:1358} INFO - 
--------------------------------------------------------------------------------
[2023-04-04 15:25:39,293] {taskinstance.py:1377} INFO - Executing <Task(PythonOperator): extrai_dados> on 2022-08-22 00:00:00+00:00
[2023-04-04 15:25:39,295] {standard_task_runner.py:52} INFO - Started process 10669 to run task
[2023-04-04 15:25:39,296] {standard_task_runner.py:79} INFO - Running: ['airflow', 'tasks', 'run', 'dados_climaticos', 'extrai_dados', 'scheduled__2022-08-22T00:00:00+00:00', '--job-id', '31', '--raw', '--subdir', 'DAGS_FOLDER/dados_climaticos.py', '--cfg-path', '/tmp/tmps1ckaspl', '--error-file', '/tmp/tmpa8bb2a7i']
[2023-04-04 15:25:39,296] {standard_task_runner.py:80} INFO - Job 31: Subtask extrai_dados
[2023-04-04 15:25:39,334] {task_command.py:370} INFO - Running <TaskInstance: dados_climaticos.extrai_dados scheduled__2022-08-22T00:00:00+00:00 [running]> on host bruno-H610M-H-DDR4
[2023-04-04 15:25:39,389] {taskinstance.py:1569} INFO - Exporting the following env vars:
AIRFLOW_CTX_DAG_OWNER=airflow
AIRFLOW_CTX_DAG_ID=dados_climaticos
AIRFLOW_CTX_TASK_ID=extrai_dados
AIRFLOW_CTX_EXECUTION_DATE=2022-08-22T00:00:00+00:00
AIRFLOW_CTX_TRY_NUMBER=1
AIRFLOW_CTX_DAG_RUN_ID=scheduled__2022-08-22T00:00:00+00:00
[2023-04-04 15:25:40,214] {python.py:173} INFO - Done. Returned value was: None
[2023-04-04 15:25:40,228] {taskinstance.py:1395} INFO - Marking task as SUCCESS. dag_id=dados_climaticos, task_id=extrai_dados, execution_date=20220822T000000, start_date=20230404T182539, end_date=20230404T182540
[2023-04-04 15:25:40,270] {local_task_job.py:156} INFO - Task exited with return code 0
[2023-04-04 15:25:40,289] {local_task_job.py:273} INFO - 0 downstream tasks scheduled from follow-on schedule check
