[2023-04-04 14:49:59,894] {taskinstance.py:1159} INFO - Dependencies all met for <TaskInstance: dados_climaticos.extrai_dados scheduled__2022-09-19T00:00:00+00:00 [queued]>
[2023-04-04 14:49:59,897] {taskinstance.py:1159} INFO - Dependencies all met for <TaskInstance: dados_climaticos.extrai_dados scheduled__2022-09-19T00:00:00+00:00 [queued]>
[2023-04-04 14:49:59,897] {taskinstance.py:1356} INFO - 
--------------------------------------------------------------------------------
[2023-04-04 14:49:59,897] {taskinstance.py:1357} INFO - Starting attempt 1 of 1
[2023-04-04 14:49:59,897] {taskinstance.py:1358} INFO - 
--------------------------------------------------------------------------------
[2023-04-04 14:49:59,918] {taskinstance.py:1377} INFO - Executing <Task(PythonOperator): extrai_dados> on 2022-09-19 00:00:00+00:00
[2023-04-04 14:49:59,920] {standard_task_runner.py:52} INFO - Started process 14784 to run task
[2023-04-04 14:49:59,922] {standard_task_runner.py:79} INFO - Running: ['airflow', 'tasks', 'run', 'dados_climaticos', 'extrai_dados', 'scheduled__2022-09-19T00:00:00+00:00', '--job-id', '37', '--raw', '--subdir', 'DAGS_FOLDER/dados_climaticos.py', '--cfg-path', '/tmp/tmpntq__h9a', '--error-file', '/tmp/tmpgpk575cv']
[2023-04-04 14:49:59,923] {standard_task_runner.py:80} INFO - Job 37: Subtask extrai_dados
[2023-04-04 14:49:59,959] {task_command.py:370} INFO - Running <TaskInstance: dados_climaticos.extrai_dados scheduled__2022-09-19T00:00:00+00:00 [running]> on host bruno-H610M-H-DDR4
[2023-04-04 14:50:00,010] {taskinstance.py:1569} INFO - Exporting the following env vars:
AIRFLOW_CTX_DAG_OWNER=airflow
AIRFLOW_CTX_DAG_ID=dados_climaticos
AIRFLOW_CTX_TASK_ID=extrai_dados
AIRFLOW_CTX_EXECUTION_DATE=2022-09-19T00:00:00+00:00
AIRFLOW_CTX_TRY_NUMBER=1
AIRFLOW_CTX_DAG_RUN_ID=scheduled__2022-09-19T00:00:00+00:00
[2023-04-04 14:50:00,680] {taskinstance.py:1889} ERROR - Task failed with exception
Traceback (most recent call last):
  File "/home/bruno/Documents/airflow_alura/venv/lib/python3.10/site-packages/airflow/operators/python.py", line 171, in execute
    return_value = self.execute_callable()
  File "/home/bruno/Documents/airflow_alura/venv/lib/python3.10/site-packages/airflow/operators/python.py", line 189, in execute_callable
    return self.python_callable(*self.op_args, **self.op_kwargs)
  File "/home/bruno/Documents/airflow_alura/dags/dados_climaticos.py", line 27, in extrai_dados
    dados = pd.read_csv(URL)
  File "/home/bruno/Documents/airflow_alura/venv/lib/python3.10/site-packages/pandas/io/parsers/readers.py", line 912, in read_csv
    return _read(filepath_or_buffer, kwds)
  File "/home/bruno/Documents/airflow_alura/venv/lib/python3.10/site-packages/pandas/io/parsers/readers.py", line 577, in _read
    parser = TextFileReader(filepath_or_buffer, **kwds)
  File "/home/bruno/Documents/airflow_alura/venv/lib/python3.10/site-packages/pandas/io/parsers/readers.py", line 1407, in __init__
    self._engine = self._make_engine(f, self.engine)
  File "/home/bruno/Documents/airflow_alura/venv/lib/python3.10/site-packages/pandas/io/parsers/readers.py", line 1661, in _make_engine
    self.handles = get_handle(
  File "/home/bruno/Documents/airflow_alura/venv/lib/python3.10/site-packages/pandas/io/common.py", line 716, in get_handle
    ioargs = _get_filepath_or_buffer(
  File "/home/bruno/Documents/airflow_alura/venv/lib/python3.10/site-packages/pandas/io/common.py", line 368, in _get_filepath_or_buffer
    with urlopen(req_info) as req:
  File "/home/bruno/Documents/airflow_alura/venv/lib/python3.10/site-packages/pandas/io/common.py", line 270, in urlopen
    return urllib.request.urlopen(*args, **kwargs)
  File "/usr/lib/python3.10/urllib/request.py", line 216, in urlopen
    return opener.open(url, data, timeout)
  File "/usr/lib/python3.10/urllib/request.py", line 525, in open
    response = meth(req, response)
  File "/usr/lib/python3.10/urllib/request.py", line 634, in http_response
    response = self.parent.error(
  File "/usr/lib/python3.10/urllib/request.py", line 563, in error
    return self._call_chain(*args)
  File "/usr/lib/python3.10/urllib/request.py", line 496, in _call_chain
    result = func(*args)
  File "/usr/lib/python3.10/urllib/request.py", line 643, in http_error_default
    raise HTTPError(req.full_url, code, msg, hdrs, fp)
urllib.error.HTTPError: HTTP Error 401: 
[2023-04-04 14:50:00,691] {taskinstance.py:1395} INFO - Marking task as FAILED. dag_id=dados_climaticos, task_id=extrai_dados, execution_date=20220919T000000, start_date=20230404T174959, end_date=20230404T175000
[2023-04-04 14:50:00,716] {standard_task_runner.py:92} ERROR - Failed to execute job 37 for task extrai_dados (HTTP Error 401: ; 14784)
[2023-04-04 14:50:00,736] {local_task_job.py:156} INFO - Task exited with return code 1
[2023-04-04 14:50:00,758] {local_task_job.py:273} INFO - 0 downstream tasks scheduled from follow-on schedule check
[2023-04-04 15:15:09,469] {taskinstance.py:1159} INFO - Dependencies all met for <TaskInstance: dados_climaticos.extrai_dados scheduled__2022-09-19T00:00:00+00:00 [queued]>
[2023-04-04 15:15:09,483] {taskinstance.py:1159} INFO - Dependencies all met for <TaskInstance: dados_climaticos.extrai_dados scheduled__2022-09-19T00:00:00+00:00 [queued]>
[2023-04-04 15:15:09,483] {taskinstance.py:1356} INFO - 
--------------------------------------------------------------------------------
[2023-04-04 15:15:09,483] {taskinstance.py:1357} INFO - Starting attempt 1 of 1
[2023-04-04 15:15:09,483] {taskinstance.py:1358} INFO - 
--------------------------------------------------------------------------------
[2023-04-04 15:15:09,504] {taskinstance.py:1377} INFO - Executing <Task(PythonOperator): extrai_dados> on 2022-09-19 00:00:00+00:00
[2023-04-04 15:15:09,507] {standard_task_runner.py:52} INFO - Started process 8678 to run task
[2023-04-04 15:15:09,510] {standard_task_runner.py:79} INFO - Running: ['airflow', 'tasks', 'run', 'dados_climaticos', 'extrai_dados', 'scheduled__2022-09-19T00:00:00+00:00', '--job-id', '35', '--raw', '--subdir', 'DAGS_FOLDER/dados_climaticos.py', '--cfg-path', '/tmp/tmpq485dm5n', '--error-file', '/tmp/tmpuvto195u']
[2023-04-04 15:15:09,510] {standard_task_runner.py:80} INFO - Job 35: Subtask extrai_dados
[2023-04-04 15:15:09,553] {task_command.py:370} INFO - Running <TaskInstance: dados_climaticos.extrai_dados scheduled__2022-09-19T00:00:00+00:00 [running]> on host bruno-H610M-H-DDR4
[2023-04-04 15:15:09,599] {taskinstance.py:1569} INFO - Exporting the following env vars:
AIRFLOW_CTX_DAG_OWNER=airflow
AIRFLOW_CTX_DAG_ID=dados_climaticos
AIRFLOW_CTX_TASK_ID=extrai_dados
AIRFLOW_CTX_EXECUTION_DATE=2022-09-19T00:00:00+00:00
AIRFLOW_CTX_TRY_NUMBER=1
AIRFLOW_CTX_DAG_RUN_ID=scheduled__2022-09-19T00:00:00+00:00
[2023-04-04 15:15:10,415] {taskinstance.py:1889} ERROR - Task failed with exception
Traceback (most recent call last):
  File "/home/bruno/Documents/airflow_alura/venv/lib/python3.10/site-packages/airflow/operators/python.py", line 171, in execute
    return_value = self.execute_callable()
  File "/home/bruno/Documents/airflow_alura/venv/lib/python3.10/site-packages/airflow/operators/python.py", line 189, in execute_callable
    return self.python_callable(*self.op_args, **self.op_kwargs)
  File "/home/bruno/Documents/airflow_alura/dags/dados_climaticos.py", line 27, in extrai_dados
    dados = pd.read_csv(URL)
  File "/home/bruno/Documents/airflow_alura/venv/lib/python3.10/site-packages/pandas/io/parsers/readers.py", line 912, in read_csv
    return _read(filepath_or_buffer, kwds)
  File "/home/bruno/Documents/airflow_alura/venv/lib/python3.10/site-packages/pandas/io/parsers/readers.py", line 577, in _read
    parser = TextFileReader(filepath_or_buffer, **kwds)
  File "/home/bruno/Documents/airflow_alura/venv/lib/python3.10/site-packages/pandas/io/parsers/readers.py", line 1407, in __init__
    self._engine = self._make_engine(f, self.engine)
  File "/home/bruno/Documents/airflow_alura/venv/lib/python3.10/site-packages/pandas/io/parsers/readers.py", line 1661, in _make_engine
    self.handles = get_handle(
  File "/home/bruno/Documents/airflow_alura/venv/lib/python3.10/site-packages/pandas/io/common.py", line 716, in get_handle
    ioargs = _get_filepath_or_buffer(
  File "/home/bruno/Documents/airflow_alura/venv/lib/python3.10/site-packages/pandas/io/common.py", line 368, in _get_filepath_or_buffer
    with urlopen(req_info) as req:
  File "/home/bruno/Documents/airflow_alura/venv/lib/python3.10/site-packages/pandas/io/common.py", line 270, in urlopen
    return urllib.request.urlopen(*args, **kwargs)
  File "/usr/lib/python3.10/urllib/request.py", line 216, in urlopen
    return opener.open(url, data, timeout)
  File "/usr/lib/python3.10/urllib/request.py", line 525, in open
    response = meth(req, response)
  File "/usr/lib/python3.10/urllib/request.py", line 634, in http_response
    response = self.parent.error(
  File "/usr/lib/python3.10/urllib/request.py", line 563, in error
    return self._call_chain(*args)
  File "/usr/lib/python3.10/urllib/request.py", line 496, in _call_chain
    result = func(*args)
  File "/usr/lib/python3.10/urllib/request.py", line 643, in http_error_default
    raise HTTPError(req.full_url, code, msg, hdrs, fp)
urllib.error.HTTPError: HTTP Error 401: 
[2023-04-04 15:15:10,434] {taskinstance.py:1395} INFO - Marking task as FAILED. dag_id=dados_climaticos, task_id=extrai_dados, execution_date=20220919T000000, start_date=20230404T181509, end_date=20230404T181510
[2023-04-04 15:15:10,450] {standard_task_runner.py:92} ERROR - Failed to execute job 35 for task extrai_dados (HTTP Error 401: ; 8678)
[2023-04-04 15:15:10,484] {local_task_job.py:156} INFO - Task exited with return code 1
[2023-04-04 15:15:10,505] {local_task_job.py:273} INFO - 0 downstream tasks scheduled from follow-on schedule check
[2023-04-04 15:18:38,341] {taskinstance.py:1159} INFO - Dependencies all met for <TaskInstance: dados_climaticos.extrai_dados scheduled__2022-09-19T00:00:00+00:00 [queued]>
[2023-04-04 15:18:38,355] {taskinstance.py:1159} INFO - Dependencies all met for <TaskInstance: dados_climaticos.extrai_dados scheduled__2022-09-19T00:00:00+00:00 [queued]>
[2023-04-04 15:18:38,355] {taskinstance.py:1356} INFO - 
--------------------------------------------------------------------------------
[2023-04-04 15:18:38,355] {taskinstance.py:1357} INFO - Starting attempt 1 of 1
[2023-04-04 15:18:38,355] {taskinstance.py:1358} INFO - 
--------------------------------------------------------------------------------
[2023-04-04 15:18:38,377] {taskinstance.py:1377} INFO - Executing <Task(PythonOperator): extrai_dados> on 2022-09-19 00:00:00+00:00
[2023-04-04 15:18:38,380] {standard_task_runner.py:52} INFO - Started process 9625 to run task
[2023-04-04 15:18:38,385] {standard_task_runner.py:79} INFO - Running: ['airflow', 'tasks', 'run', 'dados_climaticos', 'extrai_dados', 'scheduled__2022-09-19T00:00:00+00:00', '--job-id', '39', '--raw', '--subdir', 'DAGS_FOLDER/dados_climaticos.py', '--cfg-path', '/tmp/tmp6dns8jxi', '--error-file', '/tmp/tmpw_rm3l9x']
[2023-04-04 15:18:38,385] {standard_task_runner.py:80} INFO - Job 39: Subtask extrai_dados
[2023-04-04 15:18:38,438] {task_command.py:370} INFO - Running <TaskInstance: dados_climaticos.extrai_dados scheduled__2022-09-19T00:00:00+00:00 [running]> on host bruno-H610M-H-DDR4
[2023-04-04 15:18:38,500] {taskinstance.py:1569} INFO - Exporting the following env vars:
AIRFLOW_CTX_DAG_OWNER=airflow
AIRFLOW_CTX_DAG_ID=dados_climaticos
AIRFLOW_CTX_TASK_ID=extrai_dados
AIRFLOW_CTX_EXECUTION_DATE=2022-09-19T00:00:00+00:00
AIRFLOW_CTX_TRY_NUMBER=1
AIRFLOW_CTX_DAG_RUN_ID=scheduled__2022-09-19T00:00:00+00:00
[2023-04-04 15:18:39,325] {taskinstance.py:1889} ERROR - Task failed with exception
Traceback (most recent call last):
  File "/home/bruno/Documents/airflow_alura/venv/lib/python3.10/site-packages/airflow/operators/python.py", line 171, in execute
    return_value = self.execute_callable()
  File "/home/bruno/Documents/airflow_alura/venv/lib/python3.10/site-packages/airflow/operators/python.py", line 189, in execute_callable
    return self.python_callable(*self.op_args, **self.op_kwargs)
  File "/home/bruno/Documents/airflow_alura/dags/dados_climaticos.py", line 32, in extrai_dados
    dados[['datetime', 'tempmin', 'temp', 'tempax']].to_csv(
  File "/home/bruno/Documents/airflow_alura/venv/lib/python3.10/site-packages/pandas/core/frame.py", line 3766, in __getitem__
    indexer = self.columns._get_indexer_strict(key, "columns")[1]
  File "/home/bruno/Documents/airflow_alura/venv/lib/python3.10/site-packages/pandas/core/indexes/base.py", line 5876, in _get_indexer_strict
    self._raise_if_missing(keyarr, indexer, axis_name)
  File "/home/bruno/Documents/airflow_alura/venv/lib/python3.10/site-packages/pandas/core/indexes/base.py", line 5938, in _raise_if_missing
    raise KeyError(f"{not_found} not in index")
KeyError: "['tempax'] not in index"
[2023-04-04 15:18:39,338] {taskinstance.py:1395} INFO - Marking task as FAILED. dag_id=dados_climaticos, task_id=extrai_dados, execution_date=20220919T000000, start_date=20230404T181838, end_date=20230404T181839
[2023-04-04 15:18:39,414] {standard_task_runner.py:92} ERROR - Failed to execute job 39 for task extrai_dados ("['tempax'] not in index"; 9625)
[2023-04-04 15:18:39,438] {local_task_job.py:156} INFO - Task exited with return code 1
[2023-04-04 15:18:39,470] {local_task_job.py:273} INFO - 0 downstream tasks scheduled from follow-on schedule check
[2023-04-04 15:25:53,716] {taskinstance.py:1159} INFO - Dependencies all met for <TaskInstance: dados_climaticos.extrai_dados scheduled__2022-09-19T00:00:00+00:00 [queued]>
[2023-04-04 15:25:53,729] {taskinstance.py:1159} INFO - Dependencies all met for <TaskInstance: dados_climaticos.extrai_dados scheduled__2022-09-19T00:00:00+00:00 [queued]>
[2023-04-04 15:25:53,730] {taskinstance.py:1356} INFO - 
--------------------------------------------------------------------------------
[2023-04-04 15:25:53,730] {taskinstance.py:1357} INFO - Starting attempt 1 of 1
[2023-04-04 15:25:53,730] {taskinstance.py:1358} INFO - 
--------------------------------------------------------------------------------
[2023-04-04 15:25:53,751] {taskinstance.py:1377} INFO - Executing <Task(PythonOperator): extrai_dados> on 2022-09-19 00:00:00+00:00
[2023-04-04 15:25:53,753] {standard_task_runner.py:52} INFO - Started process 10772 to run task
[2023-04-04 15:25:53,757] {standard_task_runner.py:79} INFO - Running: ['airflow', 'tasks', 'run', 'dados_climaticos', 'extrai_dados', 'scheduled__2022-09-19T00:00:00+00:00', '--job-id', '39', '--raw', '--subdir', 'DAGS_FOLDER/dados_climaticos.py', '--cfg-path', '/tmp/tmpbs930oxe', '--error-file', '/tmp/tmpgwv61yuv']
[2023-04-04 15:25:53,758] {standard_task_runner.py:80} INFO - Job 39: Subtask extrai_dados
[2023-04-04 15:25:53,804] {task_command.py:370} INFO - Running <TaskInstance: dados_climaticos.extrai_dados scheduled__2022-09-19T00:00:00+00:00 [running]> on host bruno-H610M-H-DDR4
[2023-04-04 15:25:53,850] {taskinstance.py:1569} INFO - Exporting the following env vars:
AIRFLOW_CTX_DAG_OWNER=airflow
AIRFLOW_CTX_DAG_ID=dados_climaticos
AIRFLOW_CTX_TASK_ID=extrai_dados
AIRFLOW_CTX_EXECUTION_DATE=2022-09-19T00:00:00+00:00
AIRFLOW_CTX_TRY_NUMBER=1
AIRFLOW_CTX_DAG_RUN_ID=scheduled__2022-09-19T00:00:00+00:00
[2023-04-04 15:25:54,607] {python.py:173} INFO - Done. Returned value was: None
[2023-04-04 15:25:54,610] {taskinstance.py:1395} INFO - Marking task as SUCCESS. dag_id=dados_climaticos, task_id=extrai_dados, execution_date=20220919T000000, start_date=20230404T182553, end_date=20230404T182554
[2023-04-04 15:25:54,771] {local_task_job.py:156} INFO - Task exited with return code 0
[2023-04-04 15:25:54,792] {local_task_job.py:273} INFO - 0 downstream tasks scheduled from follow-on schedule check
